Workbook

Sheet Page de garde
A1: Page de garde
B5: REPUBLIQUE | I5: DU SENEGAL
B7: MINISTERE | I7: DES FINANCES ET DU BUDGET
B9: DIRECTION | I9: DIRECTION GENERALE DES IMPÔTS ET DES DOMAINES
B17: CENTRE DE DEPOT : | V17: xxxx
A23: ETATS FINANCIERS NORMALISES
A24: SYSTÈME COMPTABLE (SYSCOHADA)
B27: EXERCICE CLOS LE :
A30: DESIGNATION DE L'ENTREPRISE
C35: DENOMINATION SOCIALE :
C36: (ou nom et prénoms de l'exploitant)
C41: SIGLE USUEL :
C46: ADRESSE COMPLETE :
C51: N° D'IDENTIFICATION FISCALE :
C55: SYSTEME NORMAL
C59: Documents déposés | V59: Réservé à la Direction Générale des Impôts
C62: Fiche d'identification et renseignements divers | S62: X | V62: Date de dépôt
C64: Bilan | S64: X
C66: Compte de résultat | S66: X | V66: Nom de l'agent de DGI ayant réceptionné le dépôt
C68: Tableau des flux de trésorerie | S68: X
C70: Notes annexes | S70: X | V70: Signature de l'agent et cachet du service
C72: Nombre de pages déposées par exemplaire
C73: Nombre d'exemplaires déposés

Sheet Fiche de renseignement R1
A1: Fiche R1
I4: Dénomination sociale de l’entreprise | J4: =+'Page de garde'!L35 -> 0
I7: Adresse de l'entreprise | J7: ='Page de garde'!J46 -> 0 | AC7: Sigle usuel | AD7: =+'Page de garde'!H41 -> 0
I10: N° d'identification fiscale | J10: ='Page de garde'!N51 -> 0 | U10: Exercice clos le | V10: =+'Page de garde'!M27 -> 0 | AG10: Durée (en mois) | AH10: 12
B13: ZA | E13: EXERCICE COMPTABLE | W13: DU | Y13: 43466 | AF13: AU | AH13: 43830
B16: ZB | E16: DATE D'ARRETE EFFECTIF DES COMPTES | U16: =+V10 -> 0
B20: ZC | E20: EXERCICE PRECEDENT CLOS LE | Q20: 44196 | AK20: DUREE EXERCICE PRECEDENT EN MOIS : | AL20: 12
B24: ZD | F24: SN | I24: SN-DKR-2007-X XXXXX | W24: XX
F25: Greffe | I25: N° registre du Commerce | W25: N° répertoire des entreprises
B28: ZE | G28: XXX
G29: N° de caisse sociale | S29: N° Code importateur | AE29: Code activité principale
B32: ZF | D32: =+J4 -> 0 | AE32: =+AD7 -> 0
D33: Désignation de l'entreprise | AE33: Sigle
B36: ZG | G36: XXXXXXX | Q36: XXX | Y36: 3 | AA36: 4 | AE36: Dakar
G37: N° de téléphone | Q37: email | Y37: Code | AA37: Boîte postale | AE37: Ville
B40: ZH | D40: XXX
D41: Adresse géographique complète (Immeuble, rue, quartier, ville, pays)
B44: ZI | D44: XX
D45: Désignation précise de l'activité principale exercée par l'entreprise
D48: xxxxxx
D49: Nom, adresse et qualité de personne à contacter en cas de demande d'informations complémentaires
D52: XXXXXXXXXXXX
D53: Nom du professionnel salarié de l'entreprise ou Nom, adresse et téléphone du cabinet comptable ou du professionnel INSCRIT A L'ORDRE NATIONAL DES EXPERTS COMPTABLES ET DES COMPTABLES AGREES ayant établi les états financiers.
D56: XXXXXXXXXXX
D57: Noms et adresses du ou des commissaires au comptes
E64: Non assujettie | K64: Non (refus) | O64: Oui avec réserves | S64: X | T64: Oui sans réserves | Z64: Non assujettie | AG64: Non | AK64: X | AL64: Oui
C66: Etats financiers certifiés (cocher la case) | X66: Etats financiers approuvés par l'Assemblée Générale (cocher la case)
T69: Domiciliations bancaires
D70: Nom du signataire des états financiers | T70: Banque | AD70: Numéro de compte
T71: UBA | AD71: 93ODD
D73: Qualité du signataire des états financiers
D76: Date de signature
D83: Signature

Sheet BAL N
A1: N° Comptes | B1: Libellés | C1: S 1 Débit | D1: S 1 Crédit | E1: Mouv Débit | F1: Mouv Crédit | G1: S 2 Débit | H1: S 2 Crédit | I1: Ext 2 | J1: Ext 3 | K1: Ext 4 | L1: Ext 5 | M1: Ext 1
A2: 1013000 | B2: K souscri, appelé versé, non amorti | D2: 500000 | H2: 500000 | I2: =LEFT(A2,2) | J2: =LEFT(A2,3) | K2: =LEFT(A2,4) | L2: =LEFT(A2,5) | M2: =LEFT(A2,1)
A3: 111000 | B3: RESERVE LEGALE | D3: 100000 | H3: 100000 | I3: =LEFT(A3,2) | J3: =LEFT(A3,3) | K3: =LEFT(A3,4) | L3: =LEFT(A3,5) | M3: =LEFT(A3,1)
A4: 118000 | B4: Autres Réserves | D4: 11482807 | F4: 583865 | H4: 12066672 | I4: =LEFT(A4,2) | J4: =LEFT(A4,3) | K4: =LEFT(A4,4) | L4: =LEFT(A4,5) | M4: =LEFT(A4,1)
A5: 131000 | B5: RESULTAT NET : BENEFICE | D5: 583865 | E5: 583865 | I5: =LEFT(A5,2) | J5: =LEFT(A5,3) | K5: =LEFT(A5,4) | L5: =LEFT(A5,5) | M5: =LEFT(A5,1)
A6: 234000 | B6: INSTALLATIONS TECHNIQUES | C6: 160271186 | G6: 160271186 | I6: =LEFT(A6,2) | J6: =LEFT(A6,3) | K6: =LEFT(A6,4) | L6: =LEFT(A6,5) | M6: =LEFT(A6,1)
A7: 244100 | B7: MATERIEL DE BUREAU | C7: 2415000 | G7: 2415000 | I7: =LEFT(A7,2) | J7: =LEFT(A7,3) | K7: =LEFT(A7,4) | L7: =LEFT(A7,5) | M7: =LEFT(A7,1)
A8: 244200 | B8: Matériel et mobilier informatique | C8: 1538547 | G8: 1538547 | I8: =LEFT(A8,2) | J8: =LEFT(A8,3) | K8: =LEFT(A8,4) | L8: =LEFT(A8,5) | M8: =LEFT(A8,1)
A9: 244400 | B9: MOBILIER DE BUREAU | C9: 3601695 | G9: 3601695 | I9: =LEFT(A9,2) | J9: =LEFT(A9,3) | K9: =LEFT(A9,4) | L9: =LEFT(A9,5) | M9: =LEFT(A9,1)
A10: 283410 | B10: AMORT AMENAG & INST TECH SOL PROPRE | D10: 123093728 | F10: 33317458 | H10: 156411186 | I10: =LEFT(A10,2) | J10: =LEFT(A10,3) | K10: =LEFT(A10,4) | L10: =LEFT(A10,5) | M10: =LEFT(A10,1)
A11: 284420 | B11: AMORT MATERIEL INFORMAIQUE | D11: 928070 | F11: 395608 | H11: 1323678 | I11: =LEFT(A11,2) | J11: =LEFT(A11,3) | K11: =LEFT(A11,4) | L11: =LEFT(A11,5) | M11: =LEFT(A11,1)
A12: 284440 | B12: AMORT MOBILIER DE BUREAU | D12: 3054906 | F12: 1320594 | H12: 4375500 | I12: =LEFT(A12,2) | J12: =LEFT(A12,3) | K12: =LEFT(A12,4) | L12: =LEFT(A12,5) | M12: =LEFT(A12,1)
A13: 311100 | B13: MARCHANDISES | C13: 2500000 | E13: 2980700 | F13: 2500000 | G13: 2980700 | I13: =LEFT(A13,2) | J13: =LEFT(A13,3) | K13: =LEFT(A13,4) | L13: =LEFT(A13,5) | M13: =LEFT(A13,1)
A14: 401100 | B14: Fournisseurs | D14: 11377437 | E14: 107400631 | F14: 104261071 | H14: 8237877 | I14: =LEFT(A14,2) | J14: =LEFT(A14,3) | K14: =LEFT(A14,4) | L14: =LEFT(A14,5) | M14: =LEFT(A14,1)
A15: 411100 | B15: Clients | E15: 147229638 | F15: 147229638 | I15: =LEFT(A15,2) | J15: =LEFT(A15,3) | K15: =LEFT(A15,4) | L15: =LEFT(A15,5) | M15: =LEFT(A15,1)
A16: 422000 | B16: PERSONNEL REMUNERATIONS DUE | D16: 980000 | E16: 10160000 | F16: 9960000 | H16: 780000 | I16: =LEFT(A16,2) | J16: =LEFT(A16,3) | K16: =LEFT(A16,4) | L16: =LEFT(A16,5) | M16: =LEFT(A16,1)
A17: 431100 | B17: PRESTATIONS FAMILIALES | D17: 61740 | F17: 224910 | H17: 286650 | I17: =LEFT(A17,2) | J17: =LEFT(A17,3) | K17: =LEFT(A17,4) | L17: =LEFT(A17,5) | M17: =LEFT(A17,1)
A18: 431200 | B18: ACCIDENTS DE TRAVAIL | D18: 27720 | F18: 96390 | H18: 124110 | I18: =LEFT(A18,2) | J18: =LEFT(A18,3) | K18: =LEFT(A18,4) | L18: =LEFT(A18,5) | M18: =LEFT(A18,1)
A19: 431300 | B19: CAISSE DE RETRAITE OBLIGATOIRE | D19: 419953 | F19: 1493616 | H19: 1913569 | I19: =LEFT(A19,2) | J19: =LEFT(A19,3) | K19: =LEFT(A19,4) | L19: =LEFT(A19,5) | M19: =LEFT(A19,1)
A20: 441000 | B20: ETAT IMPOT SUR LES BENEFICES | D20: 5463975 | F20: 623854 | H20: 6087829 | I20: =LEFT(A20,2) | J20: =LEFT(A20,3) | K20: =LEFT(A20,4) | L20: =LEFT(A20,5) | M20: =LEFT(A20,1)
A21: 442200 | B21: IMPOTS ET TAXES SUR LES COLLECT PUB | D21: 3713622 | F21: 1575000 | H21: 5288622 | I21: =LEFT(A21,2) | J21: =LEFT(A21,3) | K21: =LEFT(A21,4) | L21: =LEFT(A21,5) | M21: =LEFT(A21,1)
A22: 443100 | B22: T.V.A. facturée sur ventes | E22: 22458759 | F22: 22458759 | I22: =LEFT(A22,2) | J22: =LEFT(A22,3) | K22: =LEFT(A22,4) | L22: =LEFT(A22,5) | M22: =LEFT(A22,1)
A23: 444100 | B23: État, T.V.A. due | D23: 3083795 | E23: 10754807 | F23: 8964438 | H23: 1293426 | I23: =LEFT(A23,2) | J23: =LEFT(A23,3) | K23: =LEFT(A23,4) | L23: =LEFT(A23,5) | M23: =LEFT(A23,1)
A24: 445200 | B24: T.V.A. récupérable sur achats | E24: 13522401 | F24: 13522401 | I24: =LEFT(A24,2) | J24: =LEFT(A24,3) | K24: =LEFT(A24,4) | L24: =LEFT(A24,5) | M24: =LEFT(A24,1)
A25: 447100 | B25: Impôt Général sur le revenu | D25: 20150 | E25: 449500 | F25: 500500 | H25: 71150 | I25: =LEFT(A25,2) | J25: =LEFT(A25,3) | K25: =LEFT(A25,4) | L25: =LEFT(A25,5) | M25: =LEFT(A25,1)
A26: 447200 | B26: IMPOT SUR SALAIRES | C26: 4498 | E26: 1605500 | F26: 1125900 | G26: 484098 | I26: =LEFT(A26,2) | J26: =LEFT(A26,3) | K26: =LEFT(A26,4) | L26: =LEFT(A26,5) | M26: =LEFT(A26,1)
A27: 447300 | B27: Contribution nationale | D27: 4000 | E27: 32500 | F27: 24300 | G27: 4200 | I27: =LEFT(A27,2) | J27: =LEFT(A27,3) | K27: =LEFT(A27,4) | L27: =LEFT(A27,5) | M27: =LEFT(A27,1)
A28: 447400 | B28: Contribution nationale de solidari | D28: 52807 | E28: 411112 | F28: 320073 | G28: 38232 | I28: =LEFT(A28,2) | J28: =LEFT(A28,3) | K28: =LEFT(A28,4) | L28: =LEFT(A28,5) | M28: =LEFT(A28,1)
A29: 447800 | B29: ETAT BRS | E29: 1575000 | F29: 1575000 | I29: =LEFT(A29,2) | J29: =LEFT(A29,3) | K29: =LEFT(A29,4) | L29: =LEFT(A29,5) | M29: =LEFT(A29,1)
A30: 462001 | B30: MATHAR MBOUP | D30: 4500000 | E30: 2500000 | H30: 2000000 | I30: =LEFT(A30,2) | J30: =LEFT(A30,3) | K30: =LEFT(A30,4) | L30: =LEFT(A30,5) | M30: =LEFT(A30,1)
A31: 462002 | B31: OTTAVI CARLO | D31: 10624330 | E31: 5000000 | H31: 5624330 | I31: =LEFT(A31,2) | J31: =LEFT(A31,3) | K31: =LEFT(A31,4) | L31: =LEFT(A31,5) | M31: =LEFT(A31,1)
A32: 521001 | B32: UBA | C32: 255614 | E32: 73657643 | F32: 69967213 | G32: 3946044 | I32: =LEFT(A32,2) | J32: =LEFT(A32,3) | K32: =LEFT(A32,4) | L32: =LEFT(A32,5) | M32: =LEFT(A32,1)
A33: 521002 | B33: BOA | C33: 4455707 | E33: 26035783 | F33: 28421751 | G33: 2069739 | I33: =LEFT(A33,2) | J33: =LEFT(A33,3) | K33: =LEFT(A33,4) | L33: =LEFT(A33,5) | M33: =LEFT(A33,1)
A34: 571000 | B34: CAISSE | C34: 5030658 | E34: 52397912 | F34: 49362829 | G34: 8065741 | I34: =LEFT(A34,2) | J34: =LEFT(A34,3) | K34: =LEFT(A34,4) | L34: =LEFT(A34,5) | M34: =LEFT(A34,1)
A35: 585000 | B35: VIREMENTS DE FONDS | E35: 4850000 | F35: 4850000 | I35: =LEFT(A35,2) | J35: =LEFT(A35,3) | K35: =LEFT(A35,4) | L35: =LEFT(A35,5) | M35: =LEFT(A35,1)
A36: 601100 | B36: ACHAT DE MARCHANDISES | E36: 54529241 | F36: 155999 | G36: 54373242 | I36: =LEFT(A36,2) | J36: =LEFT(A36,3) | K36: =LEFT(A36,4) | L36: =LEFT(A36,5) | M36: =LEFT(A36,1)
A37: 603100 | B37: VARIATION DES STOCKS DE MARCHANDISE | E37: 2500000 | F37: 2980700 | H37: 480700 | I37: =LEFT(A37,2) | J37: =LEFT(A37,3) | K37: =LEFT(A37,4) | L37: =LEFT(A37,5) | M37: =LEFT(A37,1)
A38: 605200 | B38: Fournitures non stockab - Electrici | E38: 5157737 | G38: 5157737 | I38: =LEFT(A38,2) | J38: =LEFT(A38,3) | K38: =LEFT(A38,4) | L38: =LEFT(A38,5) | M38: =LEFT(A38,1)
A39: 605300 | B39: Fourn non soctk. Autre énergies | E39: 574500 | G39: 574500 | I39: =LEFT(A39,2) | J39: =LEFT(A39,3) | K39: =LEFT(A39,4) | L39: =LEFT(A39,5) | M39: =LEFT(A39,1)
A40: 605700 | B40: Achats d'études et presta de servic | E40: 4900000 | G40: 4900000 | I40: =LEFT(A40,2) | J40: =LEFT(A40,3) | K40: =LEFT(A40,4) | L40: =LEFT(A40,5) | M40: =LEFT(A40,1)
...

Sheet BAL N-1
A1: N° Comptes | B1: Libellés | C1: S 1 Débit | D1: S 1 Crédit | E1: Mouv Débit | F1: Mouv Crédit | G1: S 2 Débit | H1: S 2 Crédit | I1: Ext 2 | J1: Ext 3 | K1: Ext 4 | L1: Ext 5 | M1: Ext 1
A2: 1013000 | B2: K souscri, appelé versé, non amorti | D2: 500000 | H2: 500000 | I2: =LEFT(A2,2) | J2: =LEFT(A2,3) | K2: =LEFT(A2,4) | L2: =LEFT(A2,5) | M2: =LEFT(A2,1)
A3: 111000 | B3: RESERVE LEGALE | D3: 100000 | H3: 100000 | I3: =LEFT(A3,2) | J3: =LEFT(A3,3) | K3: =LEFT(A3,4) | L3: =LEFT(A3,5) | M3: =LEFT(A3,1)
A4: 118000 | B4: Autres Réserves | D4: 4604302 | F4: 6878505 | H4: 11482807 | I4: =LEFT(A4,2) | J4: =LEFT(A4,3) | K4: =LEFT(A4,4) | L4: =LEFT(A4,5) | M4: =LEFT(A4,1)
A5: 131000 | B5: RESULTAT NET : BENEFICE | D5: 6878505 | E5: 6878505 | I5: =LEFT(A5,2) | J5: =LEFT(A5,3) | K5: =LEFT(A5,4) | L5: =LEFT(A5,5) | M5: =LEFT(A5,1)
A6: 234000 | B6: INSTALLATIONS TECHNIQUES | C6: 160271186 | G6: 160271186 | I6: =LEFT(A6,2) | J6: =LEFT(A6,3) | K6: =LEFT(A6,4) | L6: =LEFT(A6,5) | M6: =LEFT(A6,1)
A7: 244100 | B7: MATERIEL DE BUREAU | C7: 2415000 | G7: 2415000 | I7: =LEFT(A7,2) | J7: =LEFT(A7,3) | K7: =LEFT(A7,4) | L7: =LEFT(A7,5) | M7: =LEFT(A7,1)
A8: 244200 | B8: Matériel et mobilier informatique | C8: 1538547 | G8: 1538547 | I8: =LEFT(A8,2) | J8: =LEFT(A8,3) | K8: =LEFT(A8,4) | L8: =LEFT(A8,5) | M8: =LEFT(A8,1)
A9: 244400 | B9: MOBILIER DE BUREAU | C9: 3601695 | G9: 3601695 | I9: =LEFT(A9,2) | J9: =LEFT(A9,3) | K9: =LEFT(A9,4) | L9: =LEFT(A9,5) | M9: =LEFT(A9,1)
A10: 283410 | B10: AMORT AMENAG & INST TECH SOL PROPRE | D10: 70204237 | F10: 52889491 | H10: 123093728 | I10: =LEFT(A10,2) | J10: =LEFT(A10,3) | K10: =LEFT(A10,4) | L10: =LEFT(A10,5) | M10: =LEFT(A10,1)
A11: 284420 | B11: AMORT MATERIEL INFORMAIQUE | D11: 491256 | F11: 436814 | H11: 928070 | I11: =LEFT(A11,2) | J11: =LEFT(A11,3) | K11: =LEFT(A11,4) | L11: =LEFT(A11,5) | M11: =LEFT(A11,1)
A12: 284440 | B12: AMORT MOBILIER DE BUREAU | D12: 1610991 | F12: 1443915 | H12: 3054906 | I12: =LEFT(A12,2) | J12: =LEFT(A12,3) | K12: =LEFT(A12,4) | L12: =LEFT(A12,5) | M12: =LEFT(A12,1)
A13: 311100 | B13: MARCHANDISES | C13: 1800000 | E13: 2500000 | F13: 1800000 | G13: 2500000 | I13: =LEFT(A13,2) | J13: =LEFT(A13,3) | K13: =LEFT(A13,4) | L13: =LEFT(A13,5) | M13: =LEFT(A13,1)
A14: 401100 | B14: Fournisseurs | C14: 112000 | D14: 3101723 | E14: 216195687 | F14: 224583401 | H14: 11377437 | I14: =LEFT(A14,2) | J14: =LEFT(A14,3) | K14: =LEFT(A14,4) | L14: =LEFT(A14,5) | M14: =LEFT(A14,1)
A15: 411100 | B15: Clients | E15: 307818915 | F15: 307818915 | I15: =LEFT(A15,2) | J15: =LEFT(A15,3) | K15: =LEFT(A15,4) | L15: =LEFT(A15,5) | M15: =LEFT(A15,1)
A16: 422000 | B16: PERSONNEL REMUNERATIONS DUE | D16: 1110000 | E16: 13210000 | F16: 13080000 | H16: 980000 | I16: =LEFT(A16,2) | J16: =LEFT(A16,3) | K16: =LEFT(A16,4) | L16: =LEFT(A16,5) | M16: =LEFT(A16,1)
A17: 431100 | B17: PRESTATIONS FAMILIALES | D17: 88200 | E17: 317520 | F17: 291060 | H17: 61740 | I17: =LEFT(A17,2) | J17: =LEFT(A17,3) | K17: =LEFT(A17,4) | L17: =LEFT(A17,5) | M17: =LEFT(A17,1)
A18: 431200 | B18: ACCIDENTS DE TRAVAIL | D18: 12600 | E18: 109620 | F18: 124740 | H18: 27720 | I18: =LEFT(A18,2) | J18: =LEFT(A18,3) | K18: =LEFT(A18,4) | L18: =LEFT(A18,5) | M18: =LEFT(A18,1)
A19: 431300 | B19: CAISSE DE RETRAITE OBLIGATOIRE | D19: 527791 | E19: 2073396 | F19: 1965558 | H19: 419953 | I19: =LEFT(A19,2) | J19: =LEFT(A19,3) | K19: =LEFT(A19,4) | L19: =LEFT(A19,5) | M19: =LEFT(A19,1)
A20: 441000 | B20: ETAT IMPOT SUR LES BENEFICES | D20: 4963975 | F20: 500000 | H20: 5463975 | I20: =LEFT(A20,2) | J20: =LEFT(A20,3) | K20: =LEFT(A20,4) | L20: =LEFT(A20,5) | M20: =LEFT(A20,1)
A21: 442200 | B21: IMPOTS ET TAXES SUR LES COLLECT PUB | D21: 2081922 | F21: 1631700 | H21: 3713622 | I21: =LEFT(A21,2) | J21: =LEFT(A21,3) | K21: =LEFT(A21,4) | L21: =LEFT(A21,5) | M21: =LEFT(A21,1)
A22: 443100 | B22: T.V.A. facturée sur ventes | E22: 46955429 | F22: 46955429 | I22: =LEFT(A22,2) | J22: =LEFT(A22,3) | K22: =LEFT(A22,4) | L22: =LEFT(A22,5) | M22: =LEFT(A22,1)
A23: 444100 | B23: État, T.V.A. due | E23: 15872155 | F23: 18955950 | H23: 3083795 | I23: =LEFT(A23,2) | J23: =LEFT(A23,3) | K23: =LEFT(A23,4) | L23: =LEFT(A23,5) | M23: =LEFT(A23,1)
A24: 444900 | B24: État, crédit de T.V.A. à reporter | C24: 150242 | E24: 1327632 | F24: 1477874 | I24: =LEFT(A24,2) | J24: =LEFT(A24,3) | K24: =LEFT(A24,4) | L24: =LEFT(A24,5) | M24: =LEFT(A24,1)
A25: 445200 | B25: T.V.A. récupérable sur achats | E25: 28484122 | F25: 28484122 | I25: =LEFT(A25,2) | J25: =LEFT(A25,3) | K25: =LEFT(A25,4) | L25: =LEFT(A25,5) | M25: =LEFT(A25,1)
A26: 447100 | B26: Impôt Général sur le revenu | D26: 47710 | E26: 226960 | F26: 199400 | H26: 20150 | I26: =LEFT(A26,2) | J26: =LEFT(A26,3) | K26: =LEFT(A26,4) | L26: =LEFT(A26,5) | M26: =LEFT(A26,1)
A27: 447200 | B27: IMPOT SUR SALAIRES | C27: 26120 | E27: 1463978 | F27: 1485600 | G27: 4498 | I27: =LEFT(A27,2) | J27: =LEFT(A27,3) | K27: =LEFT(A27,4) | L27: =LEFT(A27,5) | M27: =LEFT(A27,1)
A28: 447300 | B28: Contribution nationale | C28: 400 | E28: 27400 | F28: 31800 | H28: 4000 | I28: =LEFT(A28,2) | J28: =LEFT(A28,3) | K28: =LEFT(A28,4) | L28: =LEFT(A28,5) | M28: =LEFT(A28,1)
A29: 447400 | B29: Contribution nationale de solidari | C29: 18065 | E29: 350328 | F29: 421200 | H29: 52807 | I29: =LEFT(A29,2) | J29: =LEFT(A29,3) | K29: =LEFT(A29,4) | L29: =LEFT(A29,5) | M29: =LEFT(A29,1)
A30: 462001 | B30: MATHAR MBOUP | D30: 35500000 | E30: 31000000 | H30: 4500000 | I30: =LEFT(A30,2) | J30: =LEFT(A30,3) | K30: =LEFT(A30,4) | L30: =LEFT(A30,5) | M30: =LEFT(A30,1)
A31: 462002 | B31: OTTAVI CARLO | D31: 41824330 | E31: 31200000 | H31: 10624330 | I31: =LEFT(A31,2) | J31: =LEFT(A31,3) | K31: =LEFT(A31,4) | L31: =LEFT(A31,5) | M31: =LEFT(A31,1)
A32: 521001 | B32: UBA | C32: 435541 | E32: 95618375 | F32: 95798302 | G32: 255614 | I32: =LEFT(A32,2) | J32: =LEFT(A32,3) | K32: =LEFT(A32,4) | L32: =LEFT(A32,5) | M32: =LEFT(A32,1)
A33: 521002 | B33: BOA | C33: 2764611 | E33: 81638267 | F33: 79947171 | G33: 4455707 | I33: =LEFT(A33,2) | J33: =LEFT(A33,3) | K33: =LEFT(A33,4) | L33: =LEFT(A33,5) | M33: =LEFT(A33,1)
A34: 571000 | B34: CAISSE | C34: 514135 | E34: 136741708 | F34: 132225185 | G34: 5030658 | I34: =LEFT(A34,2) | J34: =LEFT(A34,3) | K34: =LEFT(A34,4) | L34: =LEFT(A34,5) | M34: =LEFT(A34,1)
A35: 601100 | B35: ACHAT DE MARCHANDISES | E35: 130065506 | F35: 3527137 | G35: 126538369 | I35: =LEFT(A35,2) | J35: =LEFT(A35,3) | K35: =LEFT(A35,4) | L35: =LEFT(A35,5) | M35: =LEFT(A35,1)
A36: 603100 | B36: VARIATION DES STOCKS DE MARCHANDISE | E36: 1800000 | F36: 2500000 | H36: 700000 | I36: =LEFT(A36,2) | J36: =LEFT(A36,3) | K36: =LEFT(A36,4) | L36: =LEFT(A36,5) | M36: =LEFT(A36,1)
A37: 605000 | B37: AUTRES ACHATS | E37: 5674578 | G37: 5674578 | I37: =LEFT(A37,2) | J37: =LEFT(A37,3) | K37: =LEFT(A37,4) | L37: =LEFT(A37,5) | M37: =LEFT(A37,1)
A38: 605200 | B38: Fournitures non stockab - Electrici | E38: 1241709 | G38: 1241709 | I38: =LEFT(A38,2) | J38: =LEFT(A38,3) | K38: =LEFT(A38,4) | L38: =LEFT(A38,5) | M38: =LEFT(A38,1)
A39: 605300 | B39: Fourn non soctk. Autre énergies | E39: 6409141 | G39: 6409141 | I39: =LEFT(A39,2) | J39: =LEFT(A39,3) | K39: =LEFT(A39,4) | L39: =LEFT(A39,5) | M39: =LEFT(A39,1)
A40: 605700 | B40: Achats d'études et presta de servic | E40: 7290000 | G40: 7290000 | I40: =LEFT(A40,2) | J40: =LEFT(A40,3) | K40: =LEFT(A40,4) | L40: =LEFT(A40,5) | M40: =LEFT(A40,1)
...

Sheet Activités de l'entreprise R2
A1: Fiche R2
B4: Désignation de l'entreprise : | C4: ='Fiche de renseignement R1'!$J$4 -> 0
B5: Adresse de l'entreprise :
B6: ='Fiche de renseignement R1'!J7 -> 0 | L6: Sigle usuel : | M6: ='Fiche de renseignement R1'!AD7 -> 0
B7: N° d'identification : | L7: Exercice clos le :
B8: =+'Fiche de renseignement R1'!J10 -> 0 | K8: ='Fiche de renseignement R1'!V10 -> 0 | M8: Durée (en mois) | N8: ='Fiche de renseignement R1'!AH10 -> 12
A10: FICHE D'IDENTIFICATION ET RENSEIGNEMENTS DIVERS 2
L12: Contrôle de l'entreprise (cocher la case)
A14: ZK | B14: Forme juridique (1) | F14: 0 | G14: 2 | K14: ZQ | L14: Entreprise sous contrôle public
A16: ZL | B16: Régime fiscal (1) | F16: 2 | K16: ZR | L16: Entreprise sous contrôle privé national | Q16: X
A18: ZM | B18: Pays du siège social (1) | F18: 0 | G18: 7 | K18: ZS | L18: Entreprise sous contrôle privé étranger
A20: ZN | B20: Nbre d'établissements dans le pays | F20: 0 | G20: 1
A22: ZO | B22: Nbre d'établissements hors du pays | F22: 0 | G22: 0
B23: pour lesquels une comptabilité distincte est tenue
A25: ZP | B25: 1ère année exercice dans le pays | E25: 2 | F25: 0 | G25: 0 | H25: 1
A28: ACTIVITE DE L'ENTREPRISE
B30: DESIGNATION DE L'ACTIVITE (2) | C30: Code nomenclature d'activité (1) | K30: Valeur Ajoutée (VA) HT/ Chiffre d'affaire | M30: % activité dans le CA HT ou la VA
B33: TRAITEMENT ET EXPORTATION DE PRODUITS HALIEUTIQUES | D33: 3 | E33: 0 | F33: 0 | G33: 0 | H33: 2 | I33: 0 | L33: =IFERROR(VLOOKUP("702200",'BAL N'!A:H,8,FALSE),IFERROR(VLOOKUP(702200,'BAL N'!A:H,8,FALSE),0)) -> 0 | M33: =IFERROR(+L33/$L$59,0) -> 0
M36: =IFERROR(+L36/$L$59,0) -> 0
M39: =IFERROR(+L39/$L$59,0) -> 0
M42: =IFERROR(+L42/$L$59,0) -> 0
M45: =IFERROR(+L45/$L$59,0) -> 0
M48: =IFERROR(+L48/$L$59,0) -> 0
M51: =IFERROR(+L51/$L$59,0) -> 0
M54: =IFERROR(+L54/$L$59,0) -> 0
B57: Divers
I59: TOTAL | L59: =SUM(L32:L56) -> 0 | M59: =SUM(M32:M57) -> 0
B62: (1) Se réréfer aux tables des codes
B63: (2) Lister de manière précise les activités dans l'ordre décroissant du CAHT, ou de la valeur ajoutée (V.A.)
B64: (3) Rayer la mention inutile (utiliser de préférence la V.A.)

Sheet Dirigeants R3
A1: Fiche R3
A3: Désignation de l'entreprise | B3: ='Fiche de renseignement R1'!$J$4 -> 0
A4: Adresse de l'entreprise | B4: ='Activités de l''entreprise R2'!B6 -> 0 | D4: Sigle usuel | E4: ='Activités de l''entreprise R2'!M6 -> 0
A5: N° d'identification fiscale | B5: ='Activités de l''entreprise R2'!B8 -> 0 | C5: Exercice clos le | D5: ='Activités de l''entreprise R2'!K8 -> 0 | E5: Durée (en mois) | F5: ='Activités de l''entreprise R2'!N8 -> 12
A7: FICHE D'IDENTIFICATION ET RENSEIGNEMENTS DIVERS 3
A9: DIRIGEANTS (1)
A11: Nom | B11: Prénoms | C11: Qualité | D11: N° d'identification fiscale | E11: Adressse (BP, ville, pays)
A12: HDH | B12: HDDH | C12: HH | D12: DHD | E12: DHHH
A27: (1) Dirigeants = Président Directeur Général, Directeur Général, Adminsitrateur Général, Gérant, Autres.
A29: MEMBRES DU CONSEIL D'ADMINISTRATION
A31: Nom | B31: Prénoms | C31: Qualité | E31: Adressse (BP, ville, pays)

Sheet Tableau des Notes R4
A1: FICHE R4
A2: Désignation entité : | B2: ='Fiche de renseignement R1'!$J$4 -> 0 | D2: Excercice clos le : | E2: =+'Fiche de renseignement R1'!$V$10 -> 0
A3: Numéro d'identification : | B3: =+'Fiche de renseignement R1'!$J$10 -> 0 | D3: Durée en mois : | E3: =+'Fiche de renseignement R1'!$AH$10 -> 12
A6: FICHE RECAPITULATIVE DES NOTES ANNEXES PRESENTEES
A8: NOTES | B8: INTITULES | C8: A | E8: N/A
A9: NOTE 1 | B9: DETTES GARANTIES PAR DES SURETES REELLES
A10: NOTE 2 | B10: INFORMATIONS OBLIGATOIRES
A11: NOTE 3A | B11: IMMOBILISATION BRUTE
A12: NOTE 3B | B12: BIENS PRIS EN LOCATION ACQUISITION
A13: NOTE 3C | B13: IMMOBILISATIONS : AMORTISSEMENTS
A14: NOTE 3D | B14: IMMOBILISATIONS : PLUS-VALUES ET MOINS VALUES DE CESSION
A15: NOTE 3E | B15: INFORMATIONS SUR LES REEVALUATIONS EFFECTUEES PAR L'ENTITE
A16: NOTE 4 | B16: IMMOBILISATIONS FINANCIERES
A17: NOTE 5 | B17: ACTIF CIRCULANT HAO
A18: NOTE 6 | B18: STOCKS ET ENCOURS
A19: NOTE 7 | B19: CLIENTS PRODUITS A RECEVOIR
A20: NOTE 8 | B20: AUTRES CREANCES
... A54: NOTE 36 | B54: TABLES DES CODES

Sheet BILAN PAYSAGE
A1: BILAN PAYSAGE
A3: Désignation entité : | D3: ='Fiche de renseignement R1'!$J$4 -> 0 | I3: Excercice clos le : | J3: =+'Fiche de renseignement R1'!$V$10 -> 0
A4: Numéro d'identification : | D4: =+'Fiche de renseignement R1'!$J$10 -> 0 | I4: Durée en mois : | J4: =+'Fiche de renseignement R1'!$AH$10 -> 12
A6: REF | B6: ACTIF | C6: Note | D6: =IFERROR("Exercice au 31/12/"&YEAR('Fiche de renseignement R1'!V10),"Exercice au 31/12/N") -> Exercice au 31/12/1900 | G6: =IFERROR("Exercice au 31/12/"&YEAR('Fiche de renseignement R1'!Q20),"Exercice au 31/12/N-1") -> Exercice au 31/12/2020 | H6: REF | I6: PASSIF | J6: Note | K6: =IFERROR("Exercice au 31/12/"&YEAR('Fiche de renseignement R1'!V10),"Exercice au 31/12/N") -> Exercice au 31/12/1900 | L6: =IFERROR("Exercice au 31/12/"&YEAR('Fiche de renseignement R1'!Q20),"Exercice au 31/12/N-1") -> Exercice au 31/12/2020
D7: Brut | E7: Amorts et Dépréc. | F7: Net | G7: Net | K7: Net | L7: Net
A8: AD | B8: IMMOBILISATIONS INCORPORELLES | C8: 3 | D8: =+D9+D10+D11+D12 -> 0 | E8: =+E9+E10+E11+E12 -> 0 | F8: =+F9+F10+F11+F12 -> 0 | G8: =+G9+G10+G11+G12 -> 0 | H8: CA | I8: CAPITAL | J8: 13 | K8: =+SUMIF('BAL N'!J:J,"=101",'BAL N'!H:H)+SUMIF('BAL N'!J:J,"=102",'BAL N'!H:H)+SUMIF('BAL N'!J:J,"=103",'BAL N'!H:H)+SUMIF('BAL N'!J:J,"=104",'BAL N'!H:H) -> 0 | L8: =+SUMIF('BAL N'!J:J,"=101",'BAL N'!D:D)+SUMIF('BAL N'!J:J,"=102",'BAL N'!D:D)+SUMIF('BAL N'!J:J,"=103",'BAL N'!D:D)+SUMIF('BAL N'!J:J,"=104",'BAL N'!D:D) -> 0
A9: AE | B9: Frais de développement et de prospection | D9: =+SUMIF('BAL N'!J:J,"=211",'BAL N'!G:G)+SUMIF('BAL N'!K:K,"=2181",'BAL N'!G:G)+SUMIF('BAL N'!K:K,"=2191",'BAL N'!G:G) -> 0 | E9: =+SUMIF('BAL N'!K:K,"=2811",'BAL N'!H:H)+SUMIF('BAL N'!L:L,"=28181",'BAL N'!H:H)+SUMIF('BAL N'!L:L,"=28191",'BAL N'!H:H)+SUMIF('BAL N'!K:K,"=2911",'BAL N'!H:H)+SUMIF('BAL N'!K:K,"=2918",'BAL N'!H:H)+SUMIF('BAL N'!K:K,"=2919",'BAL N'!H:H) -> 0 | F9: =+D9-E9 -> 0 | G9: =+SUMIF('BAL N'!J:J,"=211",'BAL N'!C:C)+SUMIF('BAL N'!K:K,"=2181",'BAL N'!C:C)+SUMIF('BAL N'!K:K,"=2191",'BAL N'!C:C)-(SUMIF('BAL N'!K:K,"=2811",'BAL N'!D:D)+SUMIF('BAL N'!L:L,"=28181",'BAL N'!D:D)+SUMIF('BAL N'!L:L,"=28191",'BAL N'!D:D)+SUMIF('BAL N'!K:K,"=2911",'BAL N'!D:D)+SUMIF('BAL N'!K:K,"=2918",'BAL N'!D:D)+SUMIF('BAL N'!K:K,"=2919",'BAL N'!D:D)) -> 0 | H9: CB | I9: Apporteurs capital non appelé | J9: 13 | K9: =+SUMIF('BAL N'!J:J,"=109",'BAL N'!H:H) -> 0 | L9: =+SUMIF('BAL N'!J:J,"=109",'BAL N'!D:D) -> 0
A10: AF | B10: Brevets, licences, logiciels et droits similaires | D10: =+SUMIF('BAL N'!J:J,"=212",'BAL N'!G:G)+SUMIF('BAL N'!J:J,"=213",'BAL N'!G:G)+SUMIF('BAL N'!J:J,"=214",'BAL N'!G:G)+SUMIF('BAL N'!K:K,"=2193",'BAL N'!G:G) -> 0 | E10: =+SUMIF('BAL N'!K:K,"=2812",'BAL N'!H:H)+SUMIF('BAL N'!K:K,"=2813",'BAL N'!H:H)+SUMIF('BAL N'!K:K,"=2814",'BAL N'!H:H)+SUMIF('BAL N'!K:K,"=2912",'BAL N'!H:H)+SUMIF('BAL N'!K:K,"=2913",'BAL N'!H:H)+SUMIF('BAL N'!K:K,"=2914",'BAL N'!H:H)+SUMIF('BAL N'!K:K,"=2919",'BAL N'!H:H) -> 0 | F10: =+D10-E10 -> 0 | G10: =+SUMIF('BAL N'!J:J,"=212",'BAL N'!C:C)+SUMIF('BAL N'!J:J,"=213",'BAL N'!C:C)+SUMIF('BAL N'!J:J,"=214",'BAL N'!C:C)+SUMIF('BAL N'!K:K,"=2193",'BAL N'!C:C)-(SUMIF('BAL N'!K:K,"=2811",'BAL N'!D:D)+SUMIF('BAL N'!K:K,"=2812",'BAL N'!D:D)+SUMIF('BAL N'!K:K,"=2813",'BAL N'!D:D)+SUMIF('BAL N'!K:K,"=2814",'BAL N'!D:D)+SUMIF('BAL N'!L:L,"=28181",'BAL N'!D:D)+SUMIF('BAL N'!L:L,"=28191",'BAL N'!D:D)+SUMIF('BAL N'!K:K,"=2911",'BAL N'!D:D)+SUMIF('BAL N'!K:K,"=2912",'BAL N'!D:D)+SUMIF('BAL N'!K:K,"=2913",'BAL N'!D:D)+SUMIF('BAL N'!K:K,"=2914",'BAL N'!D:D)+SUMIF('BAL N'!K:K,"=2918",'BAL N'!D:D)+SUMIF('BAL N'!K:K,"=2919",'BAL N'!D:D)) -> 0 | H10: CD | I10: Primes liées au capital social | J10: 14 | K10: =+SUMIF('BAL N'!J:J,"=105",'BAL N'!H:H) -> 0 | L10: =+SUMIF('BAL N'!J:J,"=105",'BAL N'!D:D) -> 0
A11: AG | B11: Fonds commercial et droit au bail | D11: =+SUMIF('BAL N'!J:J,"=215",'BAL N'!G:G)+SUMIF('BAL N'!J:J,"=216",'BAL N'!G:G) -> 0 | E11: =+SUMIF('BAL N'!K:K,"=2815",'BAL N'!H:H)+SUMIF('BAL N'!K:K,"=2816",'BAL N'!H:H)+SUMIF('BAL N'!K:K,"=2915",'BAL N'!H:H)+SUMIF('BAL N'!K:K,"=2916",'BAL N'!H:H) -> 0 | F11: =+D11-E11 -> 0 | G11: =+SUMIF('BAL N'!J:J,"=215",'BAL N'!C:C)+SUMIF('BAL N'!J:J,"=216",'BAL N'!C:C)-(SUMIF('BAL N'!K:K,"=2815",'BAL N'!D:D)+SUMIF('BAL N'!K:K,"=2816",'BAL N'!D:D)+SUMIF('BAL N'!K:K,"=2915",'BAL N'!D:D)+SUMIF('BAL N'!K:K,"=2916",'BAL N'!D:D)) -> 0 | H11: CE | I11: Ecarts de réévaluation | J11: 3e | K11: =+SUMIF('BAL N'!J:J,"=106",'BAL N'!H:H) -> 0 | L11: =+SUMIF('BAL N'!J:J,"=106",'BAL N'!D:D) -> 0
A12: AH | B12: Autres immobilisations incorporelles | D12: =+SUMIF('BAL N'!J:J,"=217",'BAL N'!G:G)+SUMIF('BAL N'!J:J,"=218",'BAL N'!G:G)-SUMIF('BAL N'!K:K,"=2181",'BAL N'!G:G)+SUMIF('BAL N'!K:K,"=2198",'BAL N'!G:G) -> 0 | E12: =+SUMIF('BAL N'!K:K,"=2817",'BAL N'!H:H)+SUMIF('BAL N'!K:K,"=2818",'BAL N'!H:H)+SUMIF('BAL N'!K:K,"=2917",'BAL N'!H:H)+SUMIF('BAL N'!K:K,"=2918",'BAL N'!H:H)+SUMIF('BAL N'!K:K,"=2919",'BAL N'!H:H) -> 0 | F12: =+D12-E12 -> 0 | G12: =+SUMIF('BAL N'!J:J,"=217",'BAL N'!C:C)+SUMIF('BAL N'!J:J,"=218",'BAL N'!C:C)-SUMIF('BAL N'!K:K,"=2181",'BAL N'!C:C)+SUMIF('BAL N'!K:K,"=2198",'BAL N'!C:C)-(SUMIF('BAL N'!K:K,"=2817",'BAL N'!D:D)+SUMIF('BAL N'!K:K,"=2818",'BAL N'!D:D)+SUMIF('BAL N'!K:K,"=2917",'BAL N'!D:D)+SUMIF('BAL N'!K:K,"=2918",'BAL N'!D:D)+SUMIF('BAL N'!K:K,"=2919",'BAL N'!D:D)) -> 0 | H12: CF | I12: Réserves indisponibles | J12: 14 | K12: =+SUMIF('BAL N'!J:J,"=111",'BAL N'!H:H)+SUMIF('BAL N'!J:J,"=112",'BAL N'!H:H)+SUMIF('BAL N'!J:J,"=113",'BAL N'!H:H) -> 0 | L12: =+SUMIF('BAL N'!J:J,"=111",'BAL N'!D:D)+SUMIF('BAL N'!J:J,"=112",'BAL N'!D:D)+SUMIF('BAL N'!J:J,"=113",'BAL N'!D:D) -> 0
A13: AI | B13: IMMOBILISATIONS CORPORELLES | C13: 3 | D13: =SUM(D14:D19) -> 0 | E13: =SUM(E14:E19) -> 0 | F13: =SUM(F14:F19) -> 0 | G13: =SUM(G14:G19) -> 0 | H13: CG | I13: Réserves libres | J13: 14 | K13: =+SUMIF('BAL N'!J:J,"=118",'BAL N'!H:H) -> 0 | L13: =+SUMIF('BAL N'!J:J,"=118",'BAL N'!D:D) -> 0
A14: AJ | B14: Terrains (1) (1) dont placement en net ………../………… | D14: =+SUMIF('BAL N'!I:I,"=22",'BAL N'!G:G) -> 0 | E14: =+SUMIF('BAL N'!J:J,"=282",'BAL N'!H:H)+SUMIF('BAL N'!J:J,"=292",'BAL N'!H:H) -> 0 | F14: =+D14-E14 -> 0 | G14: =+SUMIF('BAL N'!I:I,"=22",'BAL N'!C:C)-(SUMIF('BAL N'!J:J,"=282",'BAL N'!D:D)+SUMIF('BAL N'!J:J,"=292",'BAL N'!D:D)) -> 0 | H14: CH | I14: Report à nouveau (+ ou -) | J14: 14 | K14: =+SUMIF('BAL N'!I:I,"=12",'BAL N'!H:H)-SUMIF('BAL N'!I:I,"=12",'BAL N'!G:G) -> 0 | L14: =+SUMIF('BAL N'!I:I,"=13",'BAL N'!D:D)-SUMIF('BAL N'!I:I,"=13",'BAL N'!C:C) -> 0
A15: AK | B15: Bâtiments (1) dont placement en net ………../………… | D15: =+SUMIF('BAL N'!J:J,"=231",'BAL N'!G:G)+SUMIF('BAL N'!J:J,"=232",'BAL N'!G:G)+SUMIF('BAL N'!J:J,"=233",'BAL N'!G:G)+SUMIF('BAL N'!J:J,"=237",'BAL N'!G:G)+SUMIF('BAL N'!K:K,"=2391",'BAL N'!G:G) -> 0 | E15: =+SUMIF('BAL N'!K:K,"=2831",'BAL N'!H:H)+SUMIF('BAL N'!K:K,"=2832",'BAL N'!H:H)+SUMIF('BAL N'!K:K,"=2833",'BAL N'!H:H)+SUMIF('BAL N'!K:K,"=2837",'BAL N'!H:H)+SUMIF('BAL N'!K:K,"=2931",'BAL N'!H:H)+SUMIF('BAL N'!K:K,"=2932",'BAL N'!H:H)+SUMIF('BAL N'!K:K,"=2933",'BAL N'!H:H)+SUMIF('BAL N'!K:K,"=2937",'BAL N'!H:H)+SUMIF('BAL N'!K:K,"=2939",'BAL N'!H:H) -> 0 | F15: =+D15-E15 -> 0 | G15: =+SUMIF('BAL N'!J:J,"=231",'BAL N'!C:C)+SUMIF('BAL N'!J:J,"=232",'BAL N'!C:C)+SUMIF('BAL N'!J:J,"=233",'BAL N'!C:C)+SUMIF('BAL N'!J:J,"=237",'BAL N'!C:C)++SUMIF('BAL N'!J:J,"=239",'BAL N'!C:C)-SUMIF('BAL N'!J:J,"=238",'BAL N'!D:D)-(SUMIF('BAL N'!K:K,"=2831",'BAL N'!D:D)+SUMIF('BAL N'!K:K,"=2832",'BAL N'!D:D)+SUMIF('BAL N'!K:K,"=2833",'BAL N'!D:D)+SUMIF('BAL N'!K:K,"=2837",'BAL N'!D:D)+SUMIF('BAL N'!K:K,"=2931",'BAL N'!D:D)+SUMIF('BAL N'!K:K,"=2932",'BAL N'!D:D)+SUMIF('BAL N'!K:K,"=2933",'BAL N'!D:D)+SUMIF('BAL N'!K:K,"=2937",'BAL N'!D:D)+SUMIF('BAL N'!K:K,"=2939",'BAL N'!D:D)) -> 0 | H15: CJ | I15: Résutat net de l'exercice (bénéfice + ou perte -) | K15: =+SUMIF('BAL N'!M:M,"=7",'BAL N'!H:H)+SUMIF('BAL N'!M:M,"=8",'BAL N'!H:H)-SUMIF('BAL N'!M:M,"=6",'BAL N'!G:G)-SUMIF('BAL N'!M:M,"=8",'BAL N'!G:G)+SUMIF('BAL N'!J:J,"=603",'BAL N'!H:H) -> 0 | L15: =-SUMIF('BAL N'!J:J,"=131",'BAL N'!C:C)+SUMIF('BAL N'!J:J,"=131",'BAL N'!D:D) -> 0
A16: AL | B16: Aménagements, agencements et installations | D16: =+SUMIF('BAL N'!J:J,"=234",'BAL N'!G:G)+SUMIF('BAL N'!J:J,"=235",'BAL N'!G:G)+SUMIF('BAL N'!J:J,"=238",'BAL N'!G:G)+SUMIF('BAL N'!J:J,"=239",'BAL N'!G:G) -> 0 | E16: =+SUMIF('BAL N'!K:K,"=2834",'BAL N'!H:H)+SUMIF('BAL N'!K:K,"=2835",'BAL N'!H:H)+SUMIF('BAL N'!K:K,"=2838",'BAL N'!H:H)+SUMIF('BAL N'!K:K,"=2934",'BAL N'!H:H)+SUMIF('BAL N'!K:K,"=2935",'BAL N'!H:H)+SUMIF('BAL N'!K:K,"=2938",'BAL N'!H:H)+SUMIF('BAL N'!K:K,"=2939",'BAL N'!H:H) -> 0 | F16: =+D16-E16 -> 0 | G16: =+SUMIF('BAL N'!J:J,"=234",'BAL N'!C:C)+SUMIF('BAL N'!J:J,"=235",'BAL N'!C:C)+SUMIF('BAL N'!J:J,"=238",'BAL N'!C:C)+SUMIF('BAL N'!K:K,"=2392",'BAL N'!C:C)+SUMIF('BAL N'!K:K,"=2393",'BAL N'!C:C)-(+SUMIF('BAL N'!K:K,"=2834",'BAL N'!D:D)+SUMIF('BAL N'!K:K,"=2835",'BAL N'!D:D)+SUMIF('BAL N'!K:K,"=2838",'BAL N'!D:D)+SUMIF('BAL N'!K:K,"=2934",'BAL N'!D:D)+SUMIF('BAL N'!K:K,"=2935",'BAL N'!D:D)+SUMIF('BAL N'!K:K,"=2938",'BAL N'!D:D)+SUMIF('BAL N'!K:K,"=2939",'BAL N'!D:D)) -> 0 | H16: CL | I16: Subventions d'investissement | J16: 15 | K16: =+SUMIF('BAL N'!I:I,"=14",'BAL N'!H:H) -> 0 | L16: =+SUMIF('BAL N'!I:I,"=14",'BAL N'!D:D) -> 0
A17: AM | B17: Matériel, mobilier et actifs biologiques | D17: =+SUMIF('BAL N'!I:I,"=24",'BAL N'!G:G)-SUMIF('BAL N'!J:J,"=245",'BAL N'!G:G)-SUMIF('BAL N'!K:K,"=2495",'BAL N'!G:G) -> 0 | E17: =+SUMIF('BAL N'!J:J,"=284",'BAL N'!H:H)-SUMIF('BAL N'!K:K,"=2845",'BAL N'!H:H)+SUMIF('BAL N'!J:J,"=294",'BAL N'!H:H)-SUMIF('BAL N'!K:K,"=2945",'BAL N'!H:H)-SUMIF('BAL N'!K:K,"=2949",'BAL N'!H:H) -> 0 | F17: =+D17-E17 -> 0 | G17: =+SUMIF('BAL N'!I:I,"=24",'BAL N'!C:C)-SUMIF('BAL N'!J:J,"=245",'BAL N'!C:C)-SUMIF('BAL N'!J:J,"=2495",'BAL N'!C:C)-(SUMIF('BAL N'!J:J,"=284",'BAL N'!D:D)-SUMIF('BAL N'!K:K,"=2845",'BAL N'!D:D)+SUMIF('BAL N'!J:J,"=294",'BAL N'!D:D)-SUMIF('BAL N'!K:K,"=2945",'BAL N'!D:D)-SUMIF('BAL N'!K:K,"=2949",'BAL N'!D:D)) -> 0 | H17: CM | I17: Provisions réglementées et fonds assimilés | J17: 15 | K17: =+SUMIF('BAL N'!I:I,"=15",'BAL N'!H:H) -> 0 | L17: =+SUMIF('BAL N'!I:I,"=15",'BAL N'!D:D) -> 0
A18: AN | B18: Matériel de transport | D18: =+SUMIF('BAL N'!J:J,"=245",'BAL N'!G:G)+SUMIF('BAL N'!K:K,"=2495",'BAL N'!G:G) -> 0 | E18: =+SUMIF('BAL N'!K:K,"=2845",'BAL N'!H:H)+SUMIF('BAL N'!K:K,"=2849",'BAL N'!H:H)+SUMIF('BAL N'!K:K,"=2945",'BAL N'!H:H) -> 0 | F18: =+D18-E18 -> 0 | G18: =+SUMIF('BAL N'!J:J,"=245",'BAL N'!C:C)+SUMIF('BAL N'!K:K,"=2495",'BAL N'!C:C)-(+SUMIF('BAL N'!K:K,"=2845",'BAL N'!D:D)+SUMIF('BAL N'!K:K,"=2849",'BAL N'!D:D)+SUMIF('BAL N'!K:K,"=2945",'BAL N'!D:D)) -> 0 | H18: CP | I18: TOTAL CAPITAUX PROPRES ET RESSOURCES ASSIMILEES | K18: =SUM(K8:K17) -> 0 | L18: =SUM(L8:L17) -> 0
A19: AP | B19: Avances & acomptes versés sur immobilisations | C19: 3 | D19: =+SUMIF('BAL N'!I:I,"=25",'BAL N'!G:G) -> 0 | E19: =+SUMIF('BAL N'!J:J,"=295",'BAL N'!H:H) -> 0 | F19: =+D19-E19 -> 0 | G19: =+SUMIF('BAL N'!I:I,"=25",'BAL N'!C:C)-SUMIF('BAL N'!J:J,"=295",'BAL N'!D:D) -> 0 | H19: DA | I19: Emprunts et dettes financières diverses | J19: 16 | K19: =+SUMIF('BAL N'!I:I,"=16",'BAL N'!H:H)+SUMIF('BAL N'!J:J,"=181",'BAL N'!H:H)+SUMIF('BAL N'!J:J,"=182",'BAL N'!H:H)+SUMIF('BAL N'!J:J,"=184",'BAL N'!H:H) -> 0 | L19: =+SUMIF('BAL N'!I:I,"=16",'BAL N'!D:D)+SUMIF('BAL N'!J:J,"=181",'BAL N'!D:D)+SUMIF('BAL N'!J:J,"=182",'BAL N'!D:D)+SUMIF('BAL N'!J:J,"=183",'BAL N'!D:D)+SUMIF('BAL N'!J:J,"=184",'BAL N'!D:D) -> 0
A20: AQ | B20: IMMOBILISATIONS FINANCIERES | C20: 4 | D20: =SUM(D21:D22) -> 0 | E20: =SUM(E21:E22) -> 0 | F20: =SUM(F21:F22) -> 0 | G20: =SUM(G21:G22) -> 0 | H20: DB | I20: Dettes de location acquisition | J20: 16 | K20: =+SUMIF('BAL N'!I:I,"=17",'BAL N'!H:H) -> 0 | L20: =+SUMIF('BAL N'!I:I,"=17",'BAL N'!D:D) -> 0
A21: AR | B21: Titres de participation | D21: =+SUMIF('BAL N'!I:I,"=26",'BAL N'!G:G) -> 0 | E21: =+SUMIF('BAL N'!J:J,"=296",'BAL N'!H:H) -> 0 | F21: =+D21-E21 -> 0 | G21: =+SUMIF('BAL N'!I:I,"=26",'BAL N'!C:C)-SUMIF('BAL N'!J:J,"=296",'BAL N'!D:D) -> 0 | H21: DC | I21: Provisions pour risques et charges | J21: 16 | K21: =+SUMIF('BAL N'!I:I,"=19",'BAL N'!H:H) -> 0 | L21: =+SUMIF('BAL N'!I:I,"=19",'BAL N'!D:D) -> 0
A22: AS | B22: Autres immobilisations financières | D22: =+SUMIF('BAL N'!I:I,"=27",'BAL N'!G:G) -> 0 | E22: =+SUMIF('BAL N'!J:J,"=297",'BAL N'!H:H) -> 0 | F22: =+D22-E22 -> 0 | G22: =+SUMIF('BAL N'!I:I,"=27",'BAL N'!C:C)-SUMIF('BAL N'!J:J,"=297",'BAL N'!D:D) -> 0 | H22: DD | I22: TOTAL DETTES FINANCIERES ET RESSOURCES ASSIMILEES | K22: =SUM(K19:K21) -> 0 | L22: =SUM(L19:L21) -> 0
A23: AZ | B23: TOTAL ACTIF IMMOBILISE | D23: =+D20+D13+D8 -> 0 | E23: =+E20+E13+E8 -> 0 | F23: =+F20+F13+F8 -> 0 | G23: =+G20+G13+G8 -> 0 | H23: DF | I23: TOTAL RESSOURCES STABLES
A24: BA | B24: ACTIF CIRCULANT H.A.O. | C24: 5 | D24: =+SUMIF('BAL N'!J:J,"=485",'BAL N'!G:G)+SUMIF('BAL N'!J:J,"=488",'BAL N'!G:G) -> 0 | E24: =+SUMIF('BAL N'!J:J,"=498",'BAL N'!H:H) -> 0 | F24: =+D24-E24 -> 0 | G24: =+SUMIF('BAL N'!J:J,"=485",'BAL N'!C:C)+SUMIF('BAL N'!J:J,"=488",'BAL N'!C:C)-SUMIF('BAL N'!J:J,"=498",'BAL N'!D:D) -> 0 | H24: DH | I24: Dettes circulantes HAO | J24: 5 | K24: =+SUMIF('BAL N'!J:J,"=481",'BAL N'!H:H)+SUMIF('BAL N'!J:J,"=482",'BAL N'!H:H)+SUMIF('BAL N'!J:J,"=484",'BAL N'!H:H)+SUMIF('BAL N'!K:K,"=4998",'BAL N'!H:H) -> 0 | L24: =+SUMIF('BAL N'!J:J,"=481",'BAL N'!D:D)+SUMIF('BAL N'!J:J,"=482",'BAL N'!D:D)+SUMIF('BAL N'!J:J,"=484",'BAL N'!D:D)+SUMIF('BAL N'!K:K,"=4998",'BAL N'!D:D) -> 0
A25: BB | B25: STOCKS ET ENCOURS | C25: 6 | D25: =+SUMIF('BAL N'!I:I,"=31",'BAL N'!G:G)+SUMIF('BAL N'!I:I,"=32",'BAL N'!G:G)+SUMIF('BAL N'!I:I,"=33",'BAL N'!G:G)+SUMIF('BAL N'!I:I,"=34",'BAL N'!G:G)+SUMIF('BAL N'!I:I,"=35",'BAL N'!G:G)+SUMIF('BAL N'!I:I,"=36",'BAL N'!G:G)+SUMIF('BAL N'!I:I,"=37",'BAL N'!G:G)+SUMIF('BAL N'!I:I,"=38",'BAL N'!G:G) -> 0 | E25: =+SUMIF('BAL N'!I:I,"=39",'BAL N'!H:H) -> 0 | F25: =+D25-E25 -> 0 | G25: =+SUMIF('BAL N'!I:I,"=31",'BAL N'!C:C)+SUMIF('BAL N'!I:I,"=32",'BAL N'!C:C)+SUMIF('BAL N'!I:I,"=33",'BAL N'!C:C)+SUMIF('BAL N'!I:I,"=34",'BAL N'!C:C)+SUMIF('BAL N'!I:I,"=35",'BAL N'!C:C)+SUMIF('BAL N'!I:I,"=36",'BAL N'!C:C)+SUMIF('BAL N'!I:I,"=37",'BAL N'!C:C)+SUMIF('BAL N'!I:I,"=38",'BAL N'!C:C)-SUMIF('BAL N'!I:I,"=39",'BAL N'!D:D) -> 0 | H25: DI | I25: Clients, avances reçues | J25: 7 | K25: =+SUMIF('BAL N'!J:J,"=419",'BAL N'!H:H) -> 0 | L25: =+SUMIF('BAL N'!J:J,"=419",'BAL N'!D:D) -> 0
A26: BG | B26: CREANCES ET EMPLOIS ASSIMILES | F26: =+D26-E26 -> 0 | H26: DJ | I26: Fournisseurs d'exploitation | J26: 17 | K26: =+SUMIF('BAL N'!I:I,"=40",'BAL N'!H:H)-SUMIF('BAL N'!J:J,"=409",'BAL N'!H:H) -> 0 | L26: =+SUMIF('BAL N'!J:J,"=401",'BAL N'!D:D)+SUMIF('BAL N'!J:J,"=402",'BAL N'!D:D)+SUMIF('BAL N'!J:J,"=408",'BAL N'!D:D)-SUMIF('BAL N'!J:J,"=401",'BAL N'!C:C) -> 0
A27: BH | B27: Fournisseurs, avances versées | C27: 17 | D27: =+SUMIF('BAL N'!I:I,"=40",'BAL N'!G:G)-SUMIF('BAL N'!J:J,"=490",'BAL N'!D:D) -> 0 | E27: =+SUMIF('BAL N'!J:J,"=490",'BAL N'!H:H) -> 0 | F27: =+D27-E27 -> 0 | G27: =+SUMIF('BAL N'!I:I,"=40",'BAL N'!C:C)-SUMIF('BAL N'!J:J,"=490",'BAL N'!D:D)-SUMIF('BAL N'!J:J,"409",'BAL N'!D:D) -> 0 | H27: DK | I27: Dettes fiscales et sociales | J27: 18 | K27: =+SUMIF('BAL N'!I:I,"=42",'BAL N'!H:H)+SUMIF('BAL N'!I:I,"=43",'BAL N'!H:H)+SUMIF('BAL N'!I:I,"=44",'BAL N'!H:H) -> 0 | L27: =+SUMIF('BAL N'!I:I,"=42",'BAL N'!D:D)-SUMIF('BAL N'!J:J,"=421",'BAL N'!D:D)+SUMIF('BAL N'!K:K,"=4287",'BAL N'!D:D)+SUMIF('BAL N'!I:I,"=43",'BAL N'!D:D)-SUMIF('BAL N'!K:K,"=4387",'BAL N'!D:D)+SUMIF('BAL N'!J:J,"=441",'BAL N'!D:D)+SUMIF('BAL N'!J:J,"=442",'BAL N'!D:D)+SUMIF('BAL N'!J:J,"=443",'BAL N'!D:D)+SUMIF('BAL N'!K:K,"=4441",'BAL N'!D:D)+SUMIF('BAL N'!J:J,"=446",'BAL N'!D:D)+SUMIF('BAL N'!J:J,"=447",'BAL N'!D:D)+SUMIF('BAL N'!K:K,"=4486",'BAL N'!D:D)+SUMIF('BAL N'!K:K,"=4494",'BAL N'!D:D) -> 0
A28: BI | B28: Clients | C28: 7 | D28: =+SUMIF('BAL N'!I:I,"=41",'BAL N'!G:G)-SUMIF('BAL N'!J:J,"=419",'BAL N'!G:G) -> 0 | E28: =+SUMIF('BAL N'!J:J,"=491",'BAL N'!H:H) -> 0 | F28: =+D28-E28 -> 0 | G28: =+SUMIF('BAL N'!I:I,"=41",'BAL N'!C:C)-SUMIF('BAL N'!J:J,"=491",'BAL N'!D:D)-SUMIF('BAL N'!J:J,"=411",'BAL N'!D:D) -> 0 | H28: DM | I28: Autres dettes | J28: 19 | K28: =+SUMIF('BAL N'!J:J,"=185",'BAL N'!H:H)+SUMIF('BAL N'!I:I,"=45",'BAL N'!H:H)+SUMIF('BAL N'!I:I,"=47",'BAL N'!H:H)+SUMIF('BAL N'!I:I,"=46",'BAL N'!H:H)-SUMIF('BAL N'!J:J,"=479",'BAL N'!H:H) -> 0 | L28: =+SUMIF('BAL N'!J:J,"=185",'BAL N'!D:D)+SUMIF('BAL N'!K:K,"=4712",'BAL N'!D:D)+SUMIF('BAL N'!J:J,"=472",'BAL N'!D:D)+SUMIF('BAL N'!J:J,"=477",'BAL N'!D:D)+SUMIF('BAL N'!I:I,"=46",'BAL N'!D:D)-SUMIF('BAL N'!J:J,"=4712",'BAL N'!C:C) -> 0
A29: BJ | B29: Autres créances | C29: 8 | D29: =SUMIF('BAL N'!J:J,"=185",'BAL N'!G:G)+SUMIF('BAL N'!I:I,"=42",'BAL N'!G:G)+SUMIF('BAL N'!I:I,"=43",'BAL N'!G:G)+SUMIF('BAL N'!I:I,"=44",'BAL N'!G:G)+SUMIF('BAL N'!I:I,"=45",'BAL N'!G:G)+SUMIF('BAL N'!I:I,"=46",'BAL N'!G:G)+SUMIF('BAL N'!I:I,"=47",'BAL N'!G:G)-SUMIF('BAL N'!J:J,"=478",'BAL N'!G:G) -> 0 | E29: =+SUMIF('BAL N'!J:J,"=492",'BAL N'!H:H)+SUMIF('BAL N'!J:J,"=493",'BAL N'!H:H)+SUMIF('BAL N'!J:J,"=494",'BAL N'!H:H)+SUMIF('BAL N'!J:J,"=495",'BAL N'!H:H)+SUMIF('BAL N'!J:J,"=496",'BAL N'!H:H)+SUMIF('BAL N'!J:J,"=497",'BAL N'!H:H) -> 0 | F29: =+D29-E29 -> 0 | G29: =+SUMIF('BAL N'!K:K,"=4287",'BAL N'!C:C)+SUMIF('BAL N'!K:K,"=4387",'BAL N'!C:C)+SUMIF('BAL N'!K:K,"=4449",'BAL N'!C:C)+SUMIF('BAL N'!J:J,"=421",'BAL N'!C:C)+SUMIF('BAL N'!J:J,"=445",'BAL N'!C:C)+SUMIF('BAL N'!K:K,"=4487",'BAL N'!C:C)+SUMIF('BAL N'!J:J,"=449",'BAL N'!C:C)+SUMIF('BAL N'!I:I,"=45",'BAL N'!C:C)+SUMIF('BAL N'!I:I,"=46",'BAL N'!C:C)+SUMIF('BAL N'!K:K,"=4711",'BAL N'!C:C)+SUMIF('BAL N'!J:J,"=475",'BAL N'!C:C)+SUMIF('BAL N'!J:J,"=476",'BAL N'!C:C)-(SUMIF('BAL N'!J:J,"=492",'BAL N'!D:D)+SUMIF('BAL N'!J:J,"=493",'BAL N'!D:D)+SUMIF('BAL N'!J:J,"=495",'BAL N'!D:D)+SUMIF('BAL N'!J:J,"=496",'BAL N'!D:D)+SUMIF('BAL N'!J:J,"=497",'BAL N'!D:D))-SUMIF('BAL N'!K:K,"=4711",'BAL N'!D:D) -> 0 | H29: DN | I29: Provisions pour risques à court terme | J29: 19 | K29: =+SUMIF('BAL N'!J:J,"=499",'BAL N'!H:H)+SUMIF('BAL N'!J:J,"=599",'BAL N'!H:H)-SUMIF('BAL N'!K:K,"=4998",'BAL N'!H:H) -> 0 | L29: =+SUMIF('BAL N'!J:J,"=499",'BAL N'!D:D)+SUMIF('BAL N'!J:J,"=599",'BAL N'!D:D)-SUMIF('BAL N'!K:K,"=4998",'BAL N'!D:D) -> 0
A30: BK | B30: TOTAL ACTIF CIRCULANT | D30: =SUM(D24:D29) -> 0 | E30: =SUM(E24:E29) -> 0 | F30: =SUM(F24:F29) -> 0 | G30: =SUM(G24:G29) -> 0 | H30: DP | I30: TOTAL PASSIF CIRCULANT | K30: =SUM(K24:K29) -> 0 | L30: =SUM(L24:L29) -> 0
A31: BQ | B31: Titres de placement | C31: 9 | D31: =+SUMIF('BAL N'!I:I,"=50",'BAL N'!G:G) -> 0 | E31: =+SUMIF('BAL N'!J:J,"=590",'BAL N'!H:H) -> 0 | F31: =+D31-E31 -> 0 | G31: =+SUMIF('BAL N'!I:I,"=59",'BAL N'!C:C)-SUMIF('BAL N'!J:J,"=590",'BAL N'!D:D) -> 0
A32: BR | B32: Valeurs à encaisser | C32: 10 | D32: =+SUMIF('BAL N'!I:I,"=51",'BAL N'!G:G) -> 0 | E32: =+SUMIF('BAL N'!J:J,"=591",'BAL N'!H:H) -> 0 | F32: =+D32-E32 -> 0 | G32: =+SUMIF('BAL N'!I:I,"=51",'BAL N'!C:C)-SUMIF('BAL N'!J:J,"=591",'BAL N'!D:D) -> 0 | H32: DQ | I32: Banques, crédits d'escompte | J32: 20 | K32: =+SUMIF('BAL N'!J:J,"=564",'BAL N'!H:H)+SUMIF('BAL N'!J:J,"=565",'BAL N'!H:H) -> 0 | L32: =+SUMIF('BAL N'!J:J,"=564",'BAL N'!D:D)+SUMIF('BAL N'!J:J,"=565",'BAL N'!D:D) -> 0
A33: BS | B33: Banques, chèques postaux, caisse et assimilés | C33: 11 | D33: =SUMIF('BAL N'!I:I,"=52",'BAL N'!G:G)+SUMIF('BAL N'!I:I,"=53",'BAL N'!G:G)+SUMIF('BAL N'!I:I,"=54",'BAL N'!G:G)+SUMIF('BAL N'!I:I,"=55",'BAL N'!G:G)+SUMIF('BAL N'!I:I,"=57",'BAL N'!G:G)+SUMIF('BAL N'!J:J,"=581",'BAL N'!G:G)+SUMIF('BAL N'!J:J,"=582",'BAL N'!G:G) -> 0 | E33: =+SUMIF('BAL N'!J:J,"=592",'BAL N'!H:H)+SUMIF('BAL N'!J:J,"=593",'BAL N'!H:H)+SUMIF('BAL N'!J:J,"=594",'BAL N'!H:H) -> 0 | F33: =+D33-E33 -> 0 | G33: =SUMIF('BAL N'!I:I,"=52",'BAL N'!C:C)+SUMIF('BAL N'!I:I,"=57",'BAL N'!C:C)+SUMIF('BAL N'!I:I,"=58",'BAL N'!C:C)+SUMIF('BAL N'!I:I,"=55",'BAL N'!C:C)+SUMIF('BAL N'!I:I,"=54",'BAL N'!C:C)+SUMIF('BAL N'!I:I,"=53",'BAL N'!C:C)-SUMIF('BAL N'!J:J,"=592",'BAL N'!D:D) -> 0 | H33: DR | I33: Banques, établissements financiers et crédits de trésorerie | J33: 20 | K33: =+SUMIF('BAL N'!I:I,"=52",'BAL N'!H:H)+SUMIF('BAL N'!I:I,"=53",'BAL N'!H:H)+SUMIF('BAL N'!J:J,"=561",'BAL N'!H:H)+SUMIF('BAL N'!J:J,"=566",'BAL N'!H:H) -> 0 | L33: =+SUMIF('BAL N'!I:I,"=52",'BAL N'!D:D)+SUMIF('BAL N'!J:J,"=561",'BAL N'!D:D)+SUMIF('BAL N'!J:J,"=566",'BAL N'!D:D) -> 0
A34: BT | B34: TOTAL TRESORERIE - ACTIF | D34: =SUM(D31:D33) -> 0 | E34: =SUM(E31:E33) -> 0 | F34: =SUM(F31:F33) -> 0 | G34: =SUM(G31:G33) -> 0 | H34: DT | I34: TOTAL TRESORERIE - PASSIF | K34: =+K32+K33 -> 0 | L34: =+L32+L33 -> 0
A35: BU | B35: Ecarts de conversion - Actif | C35: 12 | D35: =+SUMIF('BAL N'!J:J,"=478",'BAL N'!G:G) -> 0 | G35: =+SUMIF('BAL N'!J:J,"=478",'BAL N'!C:C) -> 0 | H35: DV | I35: Ecarts de conversion - Passif | J35: 12 | K35: =+SUMIF('BAL N'!J:J,"=479",'BAL N'!H:H) -> 0 | L35: =+SUMIF('BAL N'!J:J,"=479",'BAL N'!D:D) -> 0
A36: BZ | B36: TOTAL GENERAL | D36: =+D34+D30+D23 -> 0 | E36: =+E34+E30+E23 -> 0 | F36: =+F34+F30+F23 -> 0 | G36: =+G34+G30+G23 -> 0 | H36: DZ | I36: TOTAL GENERAL | K36: =+K34+K30+K22+K18 -> 0 | L36: =+L34+L30+L22+L18 -> 0

Sheet COMPTE DE RESULTAT
A1: COMPTE DE RESULTAT
A3: Désignation entité : | B3: ='Fiche de renseignement R1'!$J$4 -> 0 | D3: Excercice clos le : | E3: =+'Fiche de renseignement R1'!$V$10 -> 0
A4: Numéro d'identification : | B4: =+'Fiche de renseignement R1'!$J$10 -> 0 | D4: Durée en mois : | E4: =+'Fiche de renseignement R1'!$AH$10 -> 12
A6: REF | B6: LIBELLES | D6: NOTE | E6: =IFERROR("31/12/"&YEAR('Fiche de renseignement R1'!V10),"Exercice au 31/12/N") -> 31/12/1900 | F6: =IFERROR("31/12/"&YEAR('Fiche de renseignement R1'!Q20),"Exercice au 31/12/N-1") -> 31/12/2020
A7: TA | B7: Ventes de marchandises A | C7: + | D7: 21 | E7: =+SUMIF('BAL N'!J:J,"=701",'BAL N'!H:H) -> 0 | F7: =+SUMIF('BAL N-1'!J:J,"=701",'BAL N-1'!H:H) -> 0
A8: RA | B8: Achats de marchandises | C8: - | D8: 22 | E8: =+SUMIF('BAL N'!J:J,"=601",'BAL N'!G:G) -> 0 | F8: =+SUMIF('BAL N-1'!J:J,"=601",'BAL N-1'!G:G) -> 0
A9: RB | B9: Variation de stocks de marchandises | C9: -/+ | D9: 6 | E9: =-(+SUMIF('BAL N'!K:K,"=6031",'BAL N'!H:H)-SUMIF('BAL N'!K:K,"=6031",'BAL N'!G:G)) -> 0 | F9: =-(+SUMIF('BAL N-1'!K:K,"=6031",'BAL N-1'!H:H)-SUMIF('BAL N-1'!K:K,"=6031",'BAL N-1'!G:G)) -> 0
A10: XA | B10: MARGE BRUTE SUR MARCHANDISES (somme TA à RB) | E10: =+E14-E8-E9 -> 0 | F10: =+F14-F8-F9 -> 0
A11: TB | B11: Ventes de produits fabriqués B | C11: + | D11: 21 | E11: =+SUMIF('BAL N'!J:J,"=702",'BAL N'!H:H)+SUMIF('BAL N'!J:J,"=703",'BAL N'!H:H)+SUMIF('BAL N'!J:J,"=704",'BAL N'!H:H) -> 0 | F11: =+SUMIF('BAL N-1'!J:J,"=702",'BAL N-1'!H:H)+SUMIF('BAL N-1'!J:J,"=703",'BAL N-1'!H:H)+SUMIF('BAL N-1'!J:J,"=704",'BAL N-1'!H:H) -> 0
A12: TC | B12: Travaux, services vendus C | C12: + | D12: 21 | E12: =+SUMIF('BAL N'!J:J,"=705",'BAL N'!H:H)+SUMIF('BAL N'!J:J,"=706",'BAL N'!H:H) -> 0 | F12: =+SUMIF('BAL N-1'!J:J,"=705",'BAL N-1'!H:H)+SUMIF('BAL N-1'!J:J,"=706",'BAL N-1'!H:H) -> 0
A13: TD | B13: Produits accessoires D | C13: + | D13: 21 | E13: =+SUMIF('BAL N'!J:J,"=707",'BAL N'!H:H) -> 0 | F13: =+SUMIF('BAL N-1'!J:J,"=707",'BAL N-1'!H:H) -> 0
A14: XB | B14: CHIFFRE D'AFFAIRES (A + B + C + D) | E14: =+E7+E13+E12+E11 -> 0 | F14: =+F7+F13+F12+F11 -> 0
A15: TE | B15: Production stockée (ou destockage) | C15: -/+ | D15: 6 | E15: =+SUMIF('BAL N'!I:I,"=73",'BAL N'!H:H) -> 0 | F15: =+SUMIF('BAL N-1'!I:I,"=73",'BAL N-1'!H:H) -> 0
A16: TF | B16: Production immobilisée | D16: 21 | E16: =+SUMIF('BAL N'!I:I,"=72",'BAL N'!H:H) -> 0 | F16: =+SUMIF('BAL N-1'!I:I,"=72",'BAL N-1'!H:H) -> 0
A17: TG | B17: Subventions d'exploitation | D17: 21 | E17: =+SUMIF('BAL N'!I:I,"=71",'BAL N'!H:H) -> 0 | F17: =+SUMIF('BAL N-1'!I:I,"=71",'BAL N-1'!H:H) -> 0
A18: TH | B18: Autres produits | C18: + | D18: 21 | E18: =+SUMIF('BAL N'!I:I,"=75",'BAL N'!H:H) -> 0 | F18: =+SUMIF('BAL N-1'!I:I,"=75",'BAL N-1'!H:H) -> 0
A19: TI | B19: Transferts de charges d'exploitation | C19: + | D19: 12 | E19: =+SUMIF('BAL N'!J:J,"=781",'BAL N'!H:H) -> 0 | F19: =+SUMIF('BAL N-1'!J:J,"=781",'BAL N-1'!H:H) -> 0
A20: RC | B20: Achats de matières premières et fournitures liées | C20: - | D20: 22 | E20: =+SUMIF('BAL N'!J:J,"=602",'BAL N'!G:G) -> 0 | F20: =+SUMIF('BAL N-1'!J:J,"=602",'BAL N-1'!G:G) -> 0
A21: RD | B21: Variation de stocks de stocks de matières premières et fournitures liées | C21: -/+ | D21: 6 | E21: =-SUMIF('BAL N'!K:K,"=6032",'BAL N'!H:H)+SUMIF('BAL N'!K:K,"=6032",'BAL N'!G:G)-SUMIF('BAL N'!K:K,"=6034",'BAL N'!H:H)+SUMIF('BAL N'!K:K,"=6034",'BAL N'!G:G) -> 0 | F21: =-SUMIF('BAL N-1'!K:K,"=6032",'BAL N-1'!H:H)+SUMIF('BAL N-1'!K:K,"=6032",'BAL N-1'!G:G)-SUMIF('BAL N-1'!K:K,"=6034",'BAL N-1'!H:H)+SUMIF('BAL N-1'!K:K,"=6034",'BAL N-1'!G:G) -> 0
A22: RE | B22: Autres achats | C22: - | D22: 22 | E22: =+SUMIF('BAL N'!J:J,"=604",'BAL N'!G:G)+SUMIF('BAL N'!J:J,"=605",'BAL N'!G:G)+SUMIF('BAL N'!J:J,"=608",'BAL N'!G:G)+SUMIF('BAL N'!J:J,"=606",'BAL N'!G:G) -> 0 | F22: =+SUMIF('BAL N-1'!J:J,"=604",'BAL N-1'!G:G)+SUMIF('BAL N-1'!J:J,"=605",'BAL N-1'!G:G)+SUMIF('BAL N-1'!J:J,"=608",'BAL N-1'!G:G)+SUMIF('BAL N-1'!J:J,"=606",'BAL N-1'!G:G) -> 0
A23: RF | B23: Variation de stocks d'autres approvisionnements | C23: -/+ | D23: 6 | E23: =+SUMIF('BAL N'!K:K,"=6033",'BAL N'!H:H)-SUMIF('BAL N'!K:K,"=6033",'BAL N'!G:G) -> 0 | F23: =+SUMIF('BAL N-1'!K:K,"=6033",'BAL N-1'!H:H)-SUMIF('BAL N-1'!K:K,"=6033",'BAL N-1'!G:G) -> 0
A24: RG | B24: Transports | C24: - | D24: 23 | E24: =+SUMIF('BAL N'!I:I,"=61",'BAL N'!G:G) -> 0 | F24: =+SUMIF('BAL N-1'!I:I,"=61",'BAL N-1'!G:G) -> 0
A25: RH | B25: Services extérieurs | C25: - | D25: 24 | E25: =+SUMIF('BAL N'!I:I,"=62",'BAL N'!G:G)+SUMIF('BAL N'!I:I,"=63",'BAL N'!G:G) -> 0 | F25: =+SUMIF('BAL N-1'!I:I,"=62",'BAL N-1'!G:G)+SUMIF('BAL N-1'!I:I,"=63",'BAL N-1'!G:G) -> 0
A26: RI | B26: Impôts et taxes | C26: - | D26: 25 | E26: =+SUMIF('BAL N'!I:I,"=64",'BAL N'!G:G) -> 0 | F26: =+SUMIF('BAL N-1'!I:I,"=64",'BAL N-1'!G:G) -> 0
A27: RJ | B27: Autres charges | C27: - | D27: 26 | E27: =+SUMIF('BAL N'!I:I,"=65",'BAL N'!G:G) -> 0 | F27: =+SUMIF('BAL N-1'!I:I,"=65",'BAL N-1'!G:G) -> 0
A28: XC | B28: VALEUR AJOUTEE (XB + RA + RB) + (somme TE à RJ) | E28: =+E10+E15+E16+E17+E18+E19-E20-E21-E22-E23-E24-E25-E26-E27 -> 0 | F28: =+F10+F15+F16+F17+F18+F19-F20-F21-F22-F23-F24-F25-F26-F27 -> 0
A29: RK | B29: Charges de personnel | C29: - | D29: 27 | E29: =+SUMIF('BAL N'!I:I,"=66",'BAL N'!G:G) -> 0 | F29: =+SUMIF('BAL N-1'!I:I,"=66",'BAL N-1'!G:G) -> 0
A30: XD | B30: EXCEDENT BRUT D'EXPLOITATION (XC + RK) | E30: =+E28-E29 -> 0 | F30: =+F28-F29 -> 0
A31: TJ | B31: Reprises d'amortissements, provisions et dépréciations | C31: + | D31: 28 | E31: =+SUMIF('BAL N'!J:J,"=791",'BAL N'!H:H)+SUMIF('BAL N'!J:J,"=798",'BAL N'!H:H)+SUMIF('BAL N'!J:J,"=799",'BAL N'!H:H) -> 0 | F31: =+SUMIF('BAL N-1'!J:J,"=791",'BAL N-1'!H:H)+SUMIF('BAL N-1'!J:J,"=798",'BAL N-1'!H:H)+SUMIF('BAL N-1'!J:J,"=799",'BAL N-1'!H:H) -> 0
A32: RL | B32: Dotations aux amortissements, aux provisions et dépréciations | C32: - | D32: 3C & 28 | E32: =+SUMIF('BAL N'!J:J,"=681",'BAL N'!G:G)+SUMIF('BAL N'!J:J,"=691",'BAL N'!G:G) -> 0 | F32: =+SUMIF('BAL N-1'!J:J,"=681",'BAL N-1'!G:G)+SUMIF('BAL N-1'!J:J,"=691",'BAL N-1'!G:G) -> 0
A33: XE | B33: RESULTAT D'EXPLOITATION (XD + TJ + RL) | E33: =+E30+E31-E32 -> 0 | F33: =+F30+F31-F32 -> 0
A34: TK | B34: Revenus financiers et assimilés | C34: + | D34: 29 | E34: =+SUMIF('BAL N'!I:I,"=77",'BAL N'!H:H) -> 0 | F34: =+SUMIF('BAL N-1'!I:I,"=77",'BAL N-1'!H:H) -> 0
A35: TL | B35: Reprises de provisions et dépréciations financières | C35: + | D35: 28 | E35: =+SUMIF('BAL N'!J:J,"=797",'BAL N'!H:H) -> 0 | F35: =+SUMIF('BAL N-1'!J:J,"=797",'BAL N-1'!H:H) -> 0
A36: TM | B36: Tranferts de charges financières | C36: + | D36: 12 | E36: =+SUMIF('BAL N'!J:J,"=787",'BAL N'!H:H) -> 0 | F36: =+SUMIF('BAL N-1'!J:J,"=787",'BAL N-1'!H:H) -> 0
A37: RM | B37: Frais financiers et charges assimilées | C37: - | D37: 29 | E37: =+SUMIF('BAL N'!I:I,"=67",'BAL N'!G:G) -> 0 | F37: =+SUMIF('BAL N-1'!I:I,"=67",'BAL N-1'!G:G) -> 0
A38: RN | B38: Dotations aux provisions et aux dépréciations financières | C38: - | D38: 3C & 28 | E38: =SUMIF('BAL N'!J:J,"=697",'BAL N'!G:G) -> 0 | F38: =+SUMIF('BAL N-1'!J:J,"=697",'BAL N-1'!G:G) -> 0
A39: XF | B39: RESULTAT FINANCIER (somme TK à RN) | E39: =+E34+E35+E36-E37-E38 -> 0 | F39: =+F34+F35+F36-F37-F38 -> 0
A40: XG | B40: RESULTAT DES ACTIVITES ORDINAIRES (XE + XF) | E40: =+E33+E39 -> 0 | F40: =+F33+F39 -> 0
A41: TN | B41: Produits des cessions d'immobilisations | C41: + | D41: 3D | E41: =+SUMIF('BAL N'!I:I,"=82",'BAL N'!H:H) -> 0 | F41: =+SUMIF('BAL N-1'!I:I,"=82",'BAL N-1'!H:H) -> 0
A42: TO | B42: Autres produits H.A.O. | C42: + | D42: 30 | E42: =+SUMIF('BAL N'!I:I,"=84",'BAL N'!H:H)+SUMIF('BAL N'!I:I,"=86",'BAL N'!H:H)+SUMIF('BAL N'!I:I,"=88",'BAL N'!H:H) -> 0 | F42: =+SUMIF('BAL N-1'!I:I,"=84",'BAL N-1'!H:H)+SUMIF('BAL N-1'!I:I,"=86",'BAL N-1'!H:H) -> 0
...

Sheet FLUX DE TRESORERIE
A1: FLUX DE TRESORERIE
A3: Désignation entité : | B3: ='Fiche de renseignement R1'!$J$4 -> 0 | D3: Excercice clos le : | E3: =+'Fiche de renseignement R1'!$V$10 -> 0
A4: Numéro d'identification : | B4: =+'Fiche de renseignement R1'!$J$10 -> 0 | D4: Durée en mois : | E4: =+'Fiche de renseignement R1'!$AH$10 -> 12
A6: REF | B6: LIBELLES | D6: NOTE | E6: =IFERROR("31/12/"&YEAR('Fiche de renseignement R1'!V10),"Exercice au 31/12/N") -> 31/12/1900 | F6: =IFERROR("31/12/"&YEAR('Fiche de renseignement R1'!Q20),"Exercice au 31/12/N-1") -> 31/12/2020
A7: ZA | B7: Trésorerie nette au 1er janvier (Trésorerie actif N-1 - Trésorerie passif N-1) | C7: A | E7: ='BILAN PAYSAGE'!F34-'BILAN PAYSAGE'!K34 -> 0 | F7: -
B8: Flux de trésorerie provenant des activités opérationnelles
A9: FA | B9: Capacité d'Autofinancement Globale (CAFG) | E9: ='COMPTE DE RESULTAT'!E48+'COMPTE DE RESULTAT'!E32-'COMPTE DE RESULTAT'!E31-'COMPTE DE RESULTAT'!E45 -> 0 | F9: -
A10: FB | B10: - Variation d'actif circulant HAO (1)
A11: FC | B11: - Variation des stocks | E11: =+'BILAN PAYSAGE'!F25-'BILAN PAYSAGE'!G25 -> 0 | F11: -
A12: FD | B12: - Variation des créances | E12: =+('BILAN PAYSAGE'!F27-'BILAN PAYSAGE'!G27)+('BILAN PAYSAGE'!F28-'BILAN PAYSAGE'!G28)+('BILAN PAYSAGE'!F29-'BILAN PAYSAGE'!G29) -> 0 | F12: -
A13: FE | B13: + Variation du passif circulant (1) | E13: =+'BILAN PAYSAGE'!K30-'BILAN PAYSAGE'!L30 -> 0 | F13: -
B14: Variation du BF lié aux activités opérationnelles (FB + FC + FD + FE) : ……………………………………………..
A15: ZB | B15: Flux de trésorerie provenant des activités opérationnelles (somme FA à FE) | C15: B | E15: =+E9-E10-E11-E12+E13 -> 0 | F15: =IFERROR(+F9-F10-F11-F12+F13,0) -> 0
B16: Flux de trésorerie provenant des activités d'investissement
A17: FF | B17: - Décaissements liés aux acquisitions d'immobilisations incorporelles | E17: =+SUMIF('BAL N'!J:J,"=211",'BAL N'!E:E)+SUMIF('BAL N'!J:J,"=212",'BAL N'!E:E)+SUMIF('BAL N'!J:J,"=213",'BAL N'!E:E)+SUMIF('BAL N'!J:J,"=214",'BAL N'!E:E)+SUMIF('BAL N'!J:J,"=215",'BAL N'!E:E)+SUMIF('BAL N'!J:J,"=216",'BAL N'!E:E)+SUMIF('BAL N'!J:J,"=217",'BAL N'!E:E)+SUMIF('BAL N'!J:J,"=218",'BAL N'!E:E) -> 0 | F17: -
A18: FG | B18: - Décaissements liés aux acquisitions d'immobilisations corporelles | E18: =+SUMIF('BAL N'!I:I,"=22",'BAL N'!E:E)+SUMIF('BAL N'!I:I,"=23",'BAL N'!E:E)+SUMIF('BAL N'!I:I,"=24",'BAL N'!E:E) -> 0 | F18: -
A19: FH | B19: - Décaissements liés aux acquisitions d'immobilisations financières | E19: =(+SUMIF('BAL N'!I:I,"=25",'BAL N'!E:E)+SUMIF('BAL N'!I:I,"=26",'BAL N'!E:E)+SUMIF('BAL N'!I:I,"=27",'BAL N'!E:E)) -> 0 | F19: -
A20: FI | B20: + Encaissements liés aux cessions d'immobilisations incorporelles et corporelles | E20: =+SUMIF('BAL N'!I:I,"=82",'BAL N'!H:H) -> 0 | F20: -
A21: FJ | B21: + Encaissements liés aux cessions d'immobilisations financières
A22: ZC | B22: Flux de trésorerie provenant des activités d'investissement (somme FF à FJ) | C22: C | E22: =-E17-E18-E19+E20+E21 -> 0 | F22: =IFERROR(-F17-F18-F19+F20+F21,0) -> 0
B23: Flux de trésorerie provenant du financement par les capitaux propres
A24: FK | B24: + Augmentations de capital par apports nouveaux
A25: FL | B25: + Subventions d'investissements reçues | E25: =+SUMIF('BAL N'!I:I,"=14",'BAL N'!F:F) -> 0 | F25: -
A26: FM | B26: - Prélèvements sur le capital
A27: FN | B27: - Dividendes versés
A28: ZD | B28: Flux de trésorerie provenant des capitaux propres (somme FK à FN) | C28: D | E28: =+E24+E25-E26-E27 -> 0 | F28: =IFERROR(+F24+F25-F26-F27,0) -> 0
B29: Flux de trésorerie provenant du financement par les capitaux étrangers
A30: FO | B30: + Emprunts | E30: =+SUMIF('BAL N'!J:J,"=161",'BAL N'!F:F)+SUMIF('BAL N'!J:J,"=162",'BAL N'!F:F)+SUMIF('BAL N'!K:K,"=1661",'BAL N'!F:F)+SUMIF('BAL N'!K:K,"=1662",'BAL N'!F:F) -> 0 | F30: -
A31: FP | B31: + Autres dettes financières | E31: =+SUMIF('BAL N'!I:I,"=17",'BAL N'!H:H) -> 0 | F31: -
A32: FQ | B32: - Remboursements des emprunts et autres dettes financières | E32: =+SUMIF('BAL N'!I:I,"=16",'BAL N'!E:E)+SUMIF('BAL N'!I:I,"=17",'BAL N'!E:E)+SUMIF('BAL N'!I:I,"=18",'BAL N'!E:E) -> 0 | F32: -
A33: ZE | B33: Flux de trésorerie provenant des capitaux étrangers (somme FO à FQ) | C33: E | E33: =+E30+E31-E32 -> 0 | F33: =IFERROR(+F30+F31-F32,0) -> 0
A34: ZF | B34: Flux de trésorerie provenant des activités de financement (D + E) | C34: F | E34: =+E28+E33 -> 0 | F34: =+F28+F33 -> 0
A35: ZG | B35: VARIATION DE LA TRESORERIE NETTE DE LA PERIODE (B + C + F) | C35: G | E35: =+E34+E22+E15 -> 0 | F35: =IFERROR(+F34+F22+F15,0) -> 0
A36: ZH | B36: Trésorerie nette au 31 décembre (G + A) Contrôle : Trésorerie actif N - Trésorerie passif N | C36: H | E36: =+E35+E7 -> 0 | F36: =IFERROR(+F35+F7,0) -> 0
B37: Contrôle

Sheet Note 1
A1: NOTE 1 : DETTES GARANTIES PAR DES SURETES REELLES
A3: Désignation entité : | B3: ='Fiche de renseignement R1'!$J$4 -> 0 | D3: Excercice clos le : | E3: =+'Fiche de renseignement R1'!$V$10 -> 0
A4: Numéro d'identification : | B4: =+'Fiche de renseignement R1'!$J$10 -> 0 | D4: Durée en mois : | E4: =+'Fiche de renseignement R1'!$AH$10 -> 12
A7: LIBELLES | B7: Note | C7: Montant brut | D7: SURETES REELLES
D8: Hypothèques | E8: Nantissements | F8: Gages
F9: Autres
A10: Dettes financières et ressources assimilées :
A11: Emprunts obligataires convertibles | C11: =+SUMIF('BAL N'!K:K,"=1612",'BAL N'!H:H) -> 0
A12: Autres emprunts obligataires | C12: =+SUMIF('BAL N'!K:K,"=1618",'BAL N'!H:H) -> 0
A13: Emprunts et dettes des établissements de crédit | C13: =+SUMIF('BAL N'!J:J,"=162",'BAL N'!H:H) -> 0
A14: Autres dettes financières | C14: =+SUMIF('BAL N'!J:J,"=163",'BAL N'!H:H)+SUMIF('BAL N'!J:J,"=164",'BAL N'!H:H)+SUMIF('BAL N'!J:J,"=165",'BAL N'!H:H)+SUMIF('BAL N'!J:J,"=167",'BAL N'!H:H)+SUMIF('BAL N'!J:J,"=168",'BAL N'!H:H) -> 0
A15: SOUS TOTAL (1) | C15: =SUM(C11:C14) -> 0 | D15: =SUM(D11:D14) -> 0 | E15: =SUM(E11:E14) -> 0 | F15: =SUM(F11:F14) -> 0
A17: Dettes de location-acquisition :
A18: Dettes de crédit-bail immobilier | C18: =+SUMIF('BAL N'!J:J,"=172",'BAL N'!H:H) -> 0
A19: Dettes de crédit-bail mobilier | C19: =+SUMIF('BAL N'!J:J,"=173",'BAL N'!H:H) -> 0
A20: Dettes sur contrats de location-vente | C20: =+SUMIF('BAL N'!J:J,"=174",'BAL N'!H:H) -> 0
A21: Dettes sur contrats de location-acquisition | C21: =+SUMIF('BAL N'!J:J,"=176",'BAL N'!H:H) -> 0
A22: SOUS TOTAL (2) | C22: =SUM(C18:C21) -> 0 | D22: =SUM(D18:D21) -> 0 | E22: =SUM(E18:E21) -> 0 | F22: =SUM(F18:F21) -> 0
A24: Dettes du passif circulant :
A25: Fournisseurs et comptes rattachés | C25: =+SUMIF('BAL N'!I:I,"=40",'BAL N'!H:H)-SUMIF('BAL N'!J:J,"=409",'BAL N'!H:H) -> 0
A26: Clients | C26: =SUMIF('BAL N'!J:J,"=419",'BAL N'!H:H) -> 0
A27: Personnel | C27: =+SUMIF('BAL N'!I:I,"=42",'BAL N'!H:H) -> 0
A28: Sécurité sociale et organismes sociaux | C28: =+SUMIF('BAL N'!I:I,"=43",'BAL N'!H:H) -> 0
A29: Etat | C29: =+SUMIF('BAL N'!I:I,"=44",'BAL N'!H:H) -> 0
A30: Organismes internationaux | C30: =+SUMIF('BAL N'!I:I,"=45",'BAL N'!H:H) -> 0
A31: Associés et groupe | C31: =+SUMIF('BAL N'!I:I,"=46",'BAL N'!H:H) -> 0
A32: Créditeurs divers | C32: =+SUMIF('BAL N'!I:I,"=47",'BAL N'!H:H) -> 0
A33: SOUS TOTAL (3) | C33: =SUM(C25:C32) -> 0 | D33: =SUM(D25:D32) -> 0 | E33: =SUM(E25:E32) -> 0 | F33: =SUM(F25:F32) -> 0
A34: TOTAL (1) + (2) + (3) | C34: =+C15+C22+C33 -> 0 | D34: =+D15+D22+D33 -> 0 | E34: =+E15+E22+E33 -> 0 | F34: =+F15+F22+F33 -> 0
A35: ENGAGEMENTS FINANCIERS | E35: Engagements donnés | F35: Engagements reçus
A36: Engagements consentis à des entités liées
A37: Primes de remboursement non échus
A38: Avals, cautions, garanties
A39: Hypothèques, nantissements, gages, autres
A40: Effets escomptés non échus
A41: Créances commerciales et professionnelles cédées
A42: Abandons de créances conditionnels
A43: TOTAL | E43: =SUM(E36:E42) -> 0 | F43: =SUM(F36:F42) -> 0
A44: Commentaire :
A45: · Indiquer la raison d’être des suretés

Sheet Note 2
A1: NOTE 2 : INFORMATIONS OBLIGATOIRES
A3: Désignation entité : | B3: ='Fiche de renseignement R1'!$J$4 -> 0 | C3: Excercice clos le : | D3: =+'Note 1'!E3 -> 0
A4: Numéro d'identification : | B4: =+'Note 1'!B4 -> 0 | C4: Durée en mois : | D4: =+'Note 1'!E5 -> 0
A6: A - DECLARATION DE CONFORMITE AU SYSCOHADA
A7: Les états financiers sont établis en conformité avec le systéme comptable OHADA et l'acte uniforme relatif au droit comptable et à l'information financiére
A8: B - REGLES ET METHODES COMPTABLES
A9: Les états financiers ont été confectionnés dans le respect des postulats, des conventions et des régles d'évaluation édictés par le SYSCOHADA et l'Acte Uniforme
A10: C - DEROGATION AUX POSTULATS ET CONVENTIONS COMPTABLES
A11: Respect de tous les postulats et conventions comptables sans aucune dérogation
A12: D - INFORMATIONS COMPLEMENTAIRES RELATIVES AU BILAN, AU COMPTE DE RESULTAT ET AU TABLEAU DES FLUX DE TRESORERIE
