Workbook

Sheet Page de garde
A1: Page de garde
B5: REPUBLIQUE | I5: DU SENEGAL
B7: MINISTERE | I7: DES FINANCES ET DU BUDGET
B9: DIRECTION | I9: DIRECTION GENERALE DES IMPÔTS ET DES DOMAINES
B17: CENTRE DE DEPOT : | V17: xxxx
A23: ETATS FINANCIERS NORMALISES
A24: SYSTÈME COMPTABLE (SYSCOHADA)
B27: EXERCICE CLOS LE :
A30: DESIGNATION DE L'ENTREPRISE
C35: DENOMINATION SOCIALE :
C36: (ou nom et prénoms de l'exploitant)
C41: SIGLE USUEL :
C46: ADRESSE COMPLETE :
C51: N° D'IDENTIFICATION FISCALE :
C55: SYSTEME NORMAL
C59: Documents déposés | V59: Réservé à la Direction Générale des Impôts
C62: Fiche d'identification et renseignements divers | S62: X | V62: Date de dépôt
C64: Bilan | S64: X
C66: Compte de résultat | S66: X | V66: Nom de l'agent de DGI ayant réceptionné le dépôt
C68: Tableau des flux de trésorerie | S68: X
C70: Notes annexes | S70: X | V70: Signature de l'agent et cachet du service
C72: Nombre de pages déposées par exemplaire
C73: Nombre d'exemplaires déposés

Sheet Fiche de renseignement R1
A1: Fiche R1
I4: Dénomination sociale de l’entreprise | J4: =+'Page de garde'!L35 -> 0
I7: Adresse de l'entreprise | J7: ='Page de garde'!J46 -> 0 | AC7: Sigle usuel | AD7: =+'Page de garde'!H41 -> 0
I10: N° d'identification fiscale | J10: ='Page de garde'!N51 -> 0 | U10: Exercice clos le | V10: =+'Page de garde'!M27 -> 0 | AG10: Durée (en mois) | AH10: 12
B13: ZA | E13: EXERCICE COMPTABLE | W13: DU | Y13: 43466 | AF13: AU | AH13: 43830
B16: ZB | E16: DATE D'ARRETE EFFECTIF DES COMPTES | U16: =+V10 -> 0
B20: ZC | E20: EXERCICE PRECEDENT CLOS LE | Q20: 44196 | AK20: DUREE EXERCICE PRECEDENT EN MOIS : | AL20: 12
B24: ZD | F24: SN | I24: SN-DKR-2007-X XXXXX | W24: XX
F25: Greffe | I25: N° registre du Commerce | W25: N° répertoire des entreprises
B28: ZE | G28: XXX
G29: N° de caisse sociale | S29: N° Code importateur | AE29: Code activité principale
B32: ZF | D32: =+J4 -> 0 | AE32: =+AD7 -> 0
D33: Désignation de l'entreprise | AE33: Sigle
B36: ZG | G36: XXXXXXX | Q36: XXX | Y36: 3 | AA36: 4 | AE36: Dakar
G37: N° de téléphone | Q37: email | Y37: Code | AA37: Boîte postale | AE37: Ville
B40: ZH | D40: XXX
D41: Adresse géographique complète (Immeuble, rue, quartier, ville, pays)
B44: ZI | D44: XX
D45: Désignation précise de l'activité principale exercée par l'entreprise
D48: xxxxxx
D49: Nom, adresse et qualité de personne à contacter en cas de demande d'informations complémentaires
D52: XXXXXXXXXXXX
D53: Nom du professionnel salarié de l'entreprise ou Nom, adresse et téléphone du cabinet comptable ou du professionnel INSCRIT A L'ORDRE NATIONAL DES EXPERTS COMPTABLES ET DES COMPTABLES AGREES ayant établi les états financiers.
D56: XXXXXXXXXXX
D57: Noms et adresses du ou des commissaires au comptes
E64: Non assujettie | K64: Non (refus) | O64: Oui avec réserves | S64: X | T64: Oui sans réserves | Z64: Non assujettie | AG64: Non | AK64: X | AL64: Oui
C66: Etats financiers certifiés (cocher la case) | X66: Etats financiers approuvés par l'Assemblée Générale (cocher la case)
T69: Domiciliations bancaires
D70: Nom du signataire des états financiers | T70: Banque | AD70: Numéro de compte
T71: UBA | AD71: 93ODD
D73: Qualité du signataire des états financiers
D76: Date de signature
D83: Signature

Sheet BAL N
A1: N° Comptes | B1: Libellés | C1: S 1 Débit | D1: S 1 Crédit | E1: Mouv Débit | F1: Mouv Crédit | G1: S 2 Débit | H1: S 2 Crédit | I1: Ext 2 | J1: Ext 3 | K1: Ext 4 | L1: Ext 5 | M1: Ext 1
A2: 101000 | B2: Capital | D2: 145000000 | H2: 145000000 | I2: =LEFT(A2,2) -> 10 | J2: =LEFT(A2,3) -> 101 | K2: =LEFT(A2,4) -> 1010 | L2: =LEFT(A2,5) -> 10100 | M2: =LEFT(A2,1) -> 1
A3: 111000 | B3: RESERVES LEGALES | D3: 200000 | H3: 200000 | I3: =LEFT(A3,2) -> 11 | J3: =LEFT(A3,3) -> 111 | K3: =LEFT(A3,4) -> 1110 | L3: =LEFT(A3,5) -> 11100 | M3: =LEFT(A3,1) -> 1
A4: 118800 | B4: RESERVES LIBRES | D4: 118365583 | H4: 118365583 | I4: =LEFT(A4,2) -> 11 | J4: =LEFT(A4,3) -> 118 | K4: =LEFT(A4,4) -> 1188 | L4: =LEFT(A4,5) -> 11880 | M4: =LEFT(A4,1) -> 1
A5: 130100 | B5: RESULTAT EN | D5: 290958290 | H5: 290958290 | I5: =LEFT(A5,2) -> 13 | J5: =LEFT(A5,3) -> 130 | K5: =LEFT(A5,4) -> 1301 | L5: =LEFT(A5,5) -> 13010 | M5: =LEFT(A5,1) -> 1
A6: 130110 | B6: RESULTAT A AFFECTER | D6: 167236460 | H6: 167236460 | I6: =LEFT(A6,2) -> 13 | J6: =LEFT(A6,3) -> 130 | K6: =LEFT(A6,4) -> 1301 | L6: =LEFT(A6,5) -> 13011 | M6: =LEFT(A6,1) -> 1
A7: 130120 | B7: RESULTAT A AFFECTER 2021 | D7: 325128014 | H7: 325128014 | I7: =LEFT(A7,2) -> 13 | J7: =LEFT(A7,3) -> 130 | K7: =LEFT(A7,4) -> 1301 | L7: =LEFT(A7,5) -> 13012 | M7: =LEFT(A7,1) -> 1
A8: 130130 | B8: RESULTAT A AFFECTER 2022 | D8: 109430079 | H8: 109430079 | I8: =LEFT(A8,2) -> 13 | J8: =LEFT(A8,3) -> 130 | K8: =LEFT(A8,4) -> 1301 | L8: =LEFT(A8,5) -> 13013 | M8: =LEFT(A8,1) -> 1
A9: 222000 | B9: TERRAINS | C9: 55070000 | E9: 91000000 | G9: 146070000 | I9: =LEFT(A9,2) -> 22 | J9: =LEFT(A9,3) -> 222 | K9: =LEFT(A9,4) -> 2220 | L9: =LEFT(A9,5) -> 22200 | M9: =LEFT(A9,1) -> 2
A10: 229800 | B10: ETUDE TUBO GRAPHIQUE | C10: 1599000 | G10: 1599000 | I10: =LEFT(A10,2) -> 22 | J10: =LEFT(A10,3) -> 229 | K10: =LEFT(A10,4) -> 2298 | L10: =LEFT(A10,5) -> 22980 | M10: =LEFT(A10,1) -> 2
A11: 231100 | B11: BATIMENTS INDUSTRIELS | C11: 474597458 | G11: 474597458 | I11: =LEFT(A11,2) -> 23 | J11: =LEFT(A11,3) -> 231 | K11: =LEFT(A11,4) -> 2311 | L11: =LEFT(A11,5) -> 23110 | M11: =LEFT(A11,1) -> 2
A12: 231110 | B12: BATIMENT 2017 | C12: 108355497 | G12: 108355497 | I12: =LEFT(A12,2) -> 23 | J12: =LEFT(A12,3) -> 231 | K12: =LEFT(A12,4) -> 2311 | L12: =LEFT(A12,5) -> 23111 | M12: =LEFT(A12,1) -> 2
A13: 231120 | B13: BATIMENTS 2022 | E13: 518717871 | G13: 518717871 | I13: =LEFT(A13,2) -> 23 | J13: =LEFT(A13,3) -> 231 | K13: =LEFT(A13,4) -> 2311 | L13: =LEFT(A13,5) -> 23112 | M13: =LEFT(A13,1) -> 2
A14: 234100 | B14: INSTALLATION COMPLEXE SPEC SUR | C14: 268942370 | G14: 268942370 | I14: =LEFT(A14,2) -> 23 | J14: =LEFT(A14,3) -> 234 | K14: =LEFT(A14,4) -> 2341 | L14: =LEFT(A14,5) -> 23410 | M14: =LEFT(A14,1) -> 2
A15: 235000 | B15: AMENAGEMENT DE BUREAUX | C15: 152970201 | E15: 8270033 | G15: 161240234 | I15: =LEFT(A15,2) -> 23 | J15: =LEFT(A15,3) -> 235 | K15: =LEFT(A15,4) -> 2350 | L15: =LEFT(A15,5) -> 23500 | M15: =LEFT(A15,1) -> 2
A16: 238000 | B16: AUTRES INTALATION ET AGENCE | C16: 16992250 | G16: 16992250 | I16: =LEFT(A16,2) -> 23 | J16: =LEFT(A16,3) -> 238 | K16: =LEFT(A16,4) -> 2380 | L16: =LEFT(A16,5) -> 23800 | M16: =LEFT(A16,1) -> 2
A17: 239000 | B17: BATIMENT ET INSTALLATION EN COURS | C17: 518717871 | E17: 53596539 | F17: 518717871 | G17: 53596539 | I17: =LEFT(A17,2) -> 23 | J17: =LEFT(A17,3) -> 239 | K17: =LEFT(A17,4) -> 2390 | L17: =LEFT(A17,5) -> 23900 | M17: =LEFT(A17,1) -> 2
A18: 241100 | B18: MATERIEL INDUSTRIEL | C18: 393621547 | E18: 33956828 | G18: 427578375 | I18: =LEFT(A18,2) -> 24 | J18: =LEFT(A18,3) -> 241 | K18: =LEFT(A18,4) -> 2411 | L18: =LEFT(A18,5) -> 24110 | M18: =LEFT(A18,1) -> 2
A19: 241500 | B19: MATERIEL DE COMMUNICATION | C19: 496000 | G19: 496000 | I19: =LEFT(A19,2) -> 24 | J19: =LEFT(A19,3) -> 241 | K19: =LEFT(A19,4) -> 2415 | L19: =LEFT(A19,5) -> 24150 | M19: =LEFT(A19,1) -> 2
A20: 244200 | B20: MATERIEL INFORMATIQUE | C20: 20964652 | E20: 320000 | G20: 21284652 | I20: =LEFT(A20,2) -> 24 | J20: =LEFT(A20,3) -> 244 | K20: =LEFT(A20,4) -> 2442 | L20: =LEFT(A20,5) -> 24420 | M20: =LEFT(A20,1) -> 2
A21: 244400 | B21: MOBILIER DE BUREAU | C21: 4462000 | G21: 4462000 | I21: =LEFT(A21,2) -> 24 | J21: =LEFT(A21,3) -> 244 | K21: =LEFT(A21,4) -> 2444 | L21: =LEFT(A21,5) -> 24440 | M21: =LEFT(A21,1) -> 2
A22: 245100 | B22: MATERIEL DE TRANSPORT | C22: 65268881 | G22: 65268881 | I22: =LEFT(A22,2) -> 24 | J22: =LEFT(A22,3) -> 245 | K22: =LEFT(A22,4) -> 2451 | L22: =LEFT(A22,5) -> 24510 | M22: =LEFT(A22,1) -> 2
A23: 275100 | B23: DEPOT LOYER D'AVANCE | C23: 5463000 | G23: 5463000 | I23: =LEFT(A23,2) -> 27 | J23: =LEFT(A23,3) -> 275 | K23: =LEFT(A23,4) -> 2751 | L23: =LEFT(A23,5) -> 27510 | M23: =LEFT(A23,1) -> 2
A24: 275200 | B24: DEPOT POUR ELECTRICITE | C24: 6717480 | G24: 6717480 | I24: =LEFT(A24,2) -> 27 | J24: =LEFT(A24,3) -> 275 | K24: =LEFT(A24,4) -> 2752 | L24: =LEFT(A24,5) -> 27520 | M24: =LEFT(A24,1) -> 2
A25: 282980 | B25: AMORTS ETUDES TOPOGRAPHIQUE | F25: 79950 | H25: 79950 | I25: =LEFT(A25,2) -> 28 | J25: =LEFT(A25,3) -> 282 | K25: =LEFT(A25,4) -> 2829 | L25: =LEFT(A25,5) -> 28298 | M25: =LEFT(A25,1) -> 2
A26: 283110 | B26: AMORTS BATIMENT INDUSTRIELS | D26: 207100843 | F26: 55083541 | H26: 262184384 | I26: =LEFT(A26,2) -> 28 | J26: =LEFT(A26,3) -> 283 | K26: =LEFT(A26,4) -> 2831 | L26: =LEFT(A26,5) -> 28311 | M26: =LEFT(A26,1) -> 2
A27: 283410 | B27: AMOTS INST COMPL SPEC SUR SOL | D27: 102013896 | F27: 13447119 | H27: 115461015 | I27: =LEFT(A27,2) -> 28 | J27: =LEFT(A27,3) -> 283 | K27: =LEFT(A27,4) -> 2834 | L27: =LEFT(A27,5) -> 28341 | M27: =LEFT(A27,1) -> 2
A28: 283500 | B28: AMORT AMGMT DE BUREAUX | D28: 49911215 | F28: 15882284 | H28: 65793499 | I28: =LEFT(A28,2) -> 28 | J28: =LEFT(A28,3) -> 283 | K28: =LEFT(A28,4) -> 2835 | L28: =LEFT(A28,5) -> 28350 | M28: =LEFT(A28,1) -> 2
A29: 283800 | B29: AMORTS AUTRE SINSTAL &AGENCMT | D29: 11162168 | F29: 1699225 | H29: 12861393 | I29: =LEFT(A29,2) -> 28 | J29: =LEFT(A29,3) -> 283 | K29: =LEFT(A29,4) -> 2838 | L29: =LEFT(A29,5) -> 28380 | M29: =LEFT(A29,1) -> 2
A30: 284110 | B30: AMORTS MAT &OUTIL IND | D30: 231215269 | F30: 66298765 | H30: 297514034 | I30: =LEFT(A30,2) -> 28 | J30: =LEFT(A30,3) -> 284 | K30: =LEFT(A30,4) -> 2841 | L30: =LEFT(A30,5) -> 28411 | M30: =LEFT(A30,1) -> 2
A31: 284150 | B31: AMORTS MAT DE COMMUNICATION | D31: 360513 | F31: 99200 | H31: 459713 | I31: =LEFT(A31,2) -> 28 | J31: =LEFT(A31,3) -> 284 | K31: =LEFT(A31,4) -> 2841 | L31: =LEFT(A31,5) -> 28415 | M31: =LEFT(A31,1) -> 2
A32: 284420 | B32: AMOTS MAT INFORMATIQUE | D32: 13353898 | F32: 2644115 | H32: 15998013 | I32: =LEFT(A32,2) -> 28 | J32: =LEFT(A32,3) -> 284 | K32: =LEFT(A32,4) -> 2844 | L32: =LEFT(A32,5) -> 28442 | M32: =LEFT(A32,1) -> 2
A33: 284440 | B33: AMORTS MOBILIER DE BUREAU | D33: 4462000 | H33: 4462000 | I33: =LEFT(A33,2) -> 28 | J33: =LEFT(A33,3) -> 284 | K33: =LEFT(A33,4) -> 2844 | L33: =LEFT(A33,5) -> 28444 | M33: =LEFT(A33,1) -> 2
A34: 284500 | B34: AMORTS MAT DE TRANSPORT | D34: 46129364 | F34: 12293776 | H34: 58423140 | I34: =LEFT(A34,2) -> 28 | J34: =LEFT(A34,3) -> 284 | K34: =LEFT(A34,4) -> 2845 | L34: =LEFT(A34,5) -> 28450 | M34: =LEFT(A34,1) -> 2
A35: 321000 | B35: STOCK POISSONS | C35: 433749204 | E35: 365270359 | F35: 433749204 | G35: 365270359 | I35: =LEFT(A35,2) -> 32 | J35: =LEFT(A35,3) -> 321 | K35: =LEFT(A35,4) -> 3210 | L35: =LEFT(A35,5) -> 32100 | M35: =LEFT(A35,1) -> 3
A36: 401100 | B36: FOURNISSEURS | C36: 6915443168 | D36: 6915443168 | E36: 5142562463 | F36: 5142562463 | I36: =LEFT(A36,2) -> 40 | J36: =LEFT(A36,3) -> 401 | K36: =LEFT(A36,4) -> 4011 | L36: =LEFT(A36,5) -> 40110 | M36: =LEFT(A36,1) -> 4
A37: 408100 | B37: CAP | D37: 12004500 | E37: 12004500 | F37: 3938800 | H37: 3938800 | I37: =LEFT(A37,2) -> 40 | J37: =LEFT(A37,3) -> 408 | K37: =LEFT(A37,4) -> 4081 | L37: =LEFT(A37,5) -> 40810 | M37: =LEFT(A37,1) -> 4
A38: 409100 | B38: FACTURES PAYER D'AVANCE | C38: 87473353 | E38: 130837030 | F38: 87473353 | G38: 130837030 | I38: =LEFT(A38,2) -> 40 | J38: =LEFT(A38,3) -> 409 | K38: =LEFT(A38,4) -> 4091 | L38: =LEFT(A38,5) -> 40910 | M38: =LEFT(A38,1) -> 4
A39: 409200 | B39: FOURNIISSEURS D'INV.PAYES A L'AVANC | C39: 7349490 | F39: 7349490 | I39: =LEFT(A39,2) -> 40 | J39: =LEFT(A39,3) -> 409 | K39: =LEFT(A39,4) -> 4092 | L39: =LEFT(A39,5) -> 40920 | M39: =LEFT(A39,1) -> 4
A40: 411000 | B40: Clients | C40: 28202258525 | E40: 5294648115 | G40: 33496906640 | I40: =LEFT(A40,2) -> 41 | J40: =LEFT(A40,3) -> 411 | K40: =LEFT(A40,4) -> 4110 | L40: =LEFT(A40,5) -> 41100 | M40: =LEFT(A40,1) -> 4
...

Sheet BAL N-1
A1: N° Comptes | B1: Libellés | C1: S 1 Débit | D1: S 1 Crédit | E1: Mouv Débit | F1: Mouv Crédit | G1: S 2 Débit | H1: S 2 Crédit | I1: Ext 2 | J1: Ext 3 | K1: Ext 4 | L1: Ext 5 | M1: Ext 1
A2: 101000 | B2: CAPITAL | D2: 145000000 | H2: 145000000 | I2: =LEFT(A2,2) -> 10 | J2: =LEFT(A2,3) -> 101 | K2: =LEFT(A2,4) -> 1010 | L2: =LEFT(A2,5) -> 10100 | M2: =LEFT(A2,1) -> 1
A3: 111000 | B3: RESERVE LEGALE | D3: 200000 | F3: 28800000 | H3: 29000000 | I3: =LEFT(A3,2) -> 11 | J3: =LEFT(A3,3) -> 111 | K3: =LEFT(A3,4) -> 1110 | L3: =LEFT(A3,5) -> 11100 | M3: =LEFT(A3,1) -> 1
A4: 118800 | B4: RESERVES LIBRES | D4: 118365583 | F4: 951477399 | H4: 1069842982 | I4: =LEFT(A4,2) -> 11 | J4: =LEFT(A4,3) -> 118 | K4: =LEFT(A4,4) -> 1188 | L4: =LEFT(A4,5) -> 11880 | M4: =LEFT(A4,1) -> 1
A5: 130100 | B5: RESULTAT EN INTANCE D AFFECTION | D5: 290958290 | E5: 290958290 | I5: =LEFT(A5,2) -> 13 | J5: =LEFT(A5,3) -> 130 | K5: =LEFT(A5,4) -> 1301 | L5: =LEFT(A5,5) -> 13010 | M5: =LEFT(A5,1) -> 1
A6: 130110 | B6: RESULTAT A AFFECTER | D6: 167236460 | E6: 167236460 | I6: =LEFT(A6,2) -> 13 | J6: =LEFT(A6,3) -> 130 | K6: =LEFT(A6,4) -> 1301 | L6: =LEFT(A6,5) -> 13011 | M6: =LEFT(A6,1) -> 1
A7: 130120 | B7: RESULTAT A AFFECTER 2021 | D7: 325128014 | E7: 325128014 | I7: =LEFT(A7,2) -> 13 | J7: =LEFT(A7,3) -> 130 | K7: =LEFT(A7,4) -> 1301 | L7: =LEFT(A7,5) -> 13012 | M7: =LEFT(A7,1) -> 1
A8: 130130 | B8: RESULTAT A AFFECTER 2022 | D8: 109430079 | E8: 109430079 | I8: =LEFT(A8,2) -> 13 | J8: =LEFT(A8,3) -> 130 | K8: =LEFT(A8,4) -> 1301 | L8: =LEFT(A8,5) -> 13013 | M8: =LEFT(A8,1) -> 1
A9: 131000 | B9: RESULTAT NET : BENEFICE | D9: 87524556 | E9: 87524556 | I9: =LEFT(A9,2) -> 13 | J9: =LEFT(A9,3) -> 131 | K9: =LEFT(A9,4) -> 1310 | L9: =LEFT(A9,5) -> 13100 | M9: =LEFT(A9,1) -> 1
A10: 222000 | B10: TERRAINS | C10: 146070000 | E10: 107500000 | G10: 253570000 | I10: =LEFT(A10,2) -> 22 | J10: =LEFT(A10,3) -> 222 | K10: =LEFT(A10,4) -> 2220 | L10: =LEFT(A10,5) -> 22200 | M10: =LEFT(A10,1) -> 2
A11: 229800 | B11: ETUDE TUBO GRAFIQUE | C11: 1599000 | E11: 1400000 | G11: 2999000 | I11: =LEFT(A11,2) -> 22 | J11: =LEFT(A11,3) -> 229 | K11: =LEFT(A11,4) -> 2298 | L11: =LEFT(A11,5) -> 22980 | M11: =LEFT(A11,1) -> 2
A12: 231100 | B12: BATIMENTS INDUSTRIELS | C12: 474597458 | G12: 474597458 | I12: =LEFT(A12,2) -> 23 | J12: =LEFT(A12,3) -> 231 | K12: =LEFT(A12,4) -> 2311 | L12: =LEFT(A12,5) -> 23110 | M12: =LEFT(A12,1) -> 2
A13: 231110 | B13: BATIMENTS AUTRES | C13: 108355497 | G13: 108355497 | I13: =LEFT(A13,2) -> 23 | J13: =LEFT(A13,3) -> 231 | K13: =LEFT(A13,4) -> 2311 | L13: =LEFT(A13,5) -> 23111 | M13: =LEFT(A13,1) -> 2
A14: 231120 | B14: AUTRES BATIMENTS | C14: 518717871 | G14: 518717871 | I14: =LEFT(A14,2) -> 23 | J14: =LEFT(A14,3) -> 231 | K14: =LEFT(A14,4) -> 2311 | L14: =LEFT(A14,5) -> 23112 | M14: =LEFT(A14,1) -> 2
A15: 234100 | B15: INSTALLATION COMPLEXE SPEC | C15: 268942370 | G15: 268942370 | I15: =LEFT(A15,2) -> 23 | J15: =LEFT(A15,3) -> 234 | K15: =LEFT(A15,4) -> 2341 | L15: =LEFT(A15,5) -> 23410 | M15: =LEFT(A15,1) -> 2
A16: 235100 | B16: AMENAG BUREAU ET INSTALLATION | C16: 161240234 | G16: 161240234 | I16: =LEFT(A16,2) -> 23 | J16: =LEFT(A16,3) -> 235 | K16: =LEFT(A16,4) -> 2351 | L16: =LEFT(A16,5) -> 23510 | M16: =LEFT(A16,1) -> 2
A17: 238000 | B17: AUTRES INTALLA ET AGENCEM | C17: 16992250 | E17: 1838250 | G17: 18830500 | I17: =LEFT(A17,2) -> 23 | J17: =LEFT(A17,3) -> 238 | K17: =LEFT(A17,4) -> 2380 | L17: =LEFT(A17,5) -> 23800 | M17: =LEFT(A17,1) -> 2
A18: 239000 | B18: BATIMENT ET INSTAL EN COURS | C18: 53596539 | E18: 49513650 | G18: 103110189 | I18: =LEFT(A18,2) -> 23 | J18: =LEFT(A18,3) -> 239 | K18: =LEFT(A18,4) -> 2390 | L18: =LEFT(A18,5) -> 23900 | M18: =LEFT(A18,1) -> 2
A19: 241100 | B19: MATERIEL INDUSTRIEL | C19: 427578375 | E19: 20108194 | G19: 447686569 | I19: =LEFT(A19,2) -> 24 | J19: =LEFT(A19,3) -> 241 | K19: =LEFT(A19,4) -> 2411 | L19: =LEFT(A19,5) -> 24110 | M19: =LEFT(A19,1) -> 2
A20: 241500 | B20: MATERIEL DE COMMUNICATION | C20: 496000 | G20: 496000 | I20: =LEFT(A20,2) -> 24 | J20: =LEFT(A20,3) -> 241 | K20: =LEFT(A20,4) -> 2415 | L20: =LEFT(A20,5) -> 24150 | M20: =LEFT(A20,1) -> 2
A21: 244100 | B21: MATERIEL DE BUREAU | E21: 100000 | G21: 100000 | I21: =LEFT(A21,2) -> 24 | J21: =LEFT(A21,3) -> 244 | K21: =LEFT(A21,4) -> 2441 | L21: =LEFT(A21,5) -> 24410 | M21: =LEFT(A21,1) -> 2
A22: 244200 | B22: Matériel et mobilier informatique | C22: 21284652 | E22: 474000 | G22: 21758652 | I22: =LEFT(A22,2) -> 24 | J22: =LEFT(A22,3) -> 244 | K22: =LEFT(A22,4) -> 2442 | L22: =LEFT(A22,5) -> 24420 | M22: =LEFT(A22,1) -> 2
A23: 244400 | B23: MOBILIER DE BUREAU | C23: 4462000 | G23: 4462000 | I23: =LEFT(A23,2) -> 24 | J23: =LEFT(A23,3) -> 244 | K23: =LEFT(A23,4) -> 2444 | L23: =LEFT(A23,5) -> 24440 | M23: =LEFT(A23,1) -> 2
A24: 245100 | B24: Matériel automobile | C24: 65268881 | E24: 90000 | G24: 65358881 | I24: =LEFT(A24,2) -> 24 | J24: =LEFT(A24,3) -> 245 | K24: =LEFT(A24,4) -> 2451 | L24: =LEFT(A24,5) -> 24510 | M24: =LEFT(A24,1) -> 2
A25: 272000 | B25: PRET AU PERSONNEL | E25: 10138000 | F25: 6558000 | G25: 3580000 | I25: =LEFT(A25,2) -> 27 | J25: =LEFT(A25,3) -> 272 | K25: =LEFT(A25,4) -> 2720 | L25: =LEFT(A25,5) -> 27200 | M25: =LEFT(A25,1) -> 2
A26: 272100 | B26: PRET AUX MAREYEUR | E26: 2318147 | G26: 2318147 | I26: =LEFT(A26,2) -> 27 | J26: =LEFT(A26,3) -> 272 | K26: =LEFT(A26,4) -> 2721 | L26: =LEFT(A26,5) -> 27210 | M26: =LEFT(A26,1) -> 2
A27: 275100 | B27: DEPOTS ET CAUT POUR LOYERS D'AVANCE | C27: 5463000 | G27: 5463000 | I27: =LEFT(A27,2) -> 27 | J27: =LEFT(A27,3) -> 275 | K27: =LEFT(A27,4) -> 2751 | L27: =LEFT(A27,5) -> 27510 | M27: =LEFT(A27,1) -> 2
A28: 275200 | B28: DEPOT POUR ELECTRICITE | C28: 6717480 | G28: 6717480 | I28: =LEFT(A28,2) -> 27 | J28: =LEFT(A28,3) -> 275 | K28: =LEFT(A28,4) -> 2752 | L28: =LEFT(A28,5) -> 27520 | M28: =LEFT(A28,1) -> 2
A29: 282980 | B29: AMORTS ETUDES TOPOGRAPHIQUE | D29: 79950 | F29: 83450 | H29: 163400 | I29: =LEFT(A29,2) -> 28 | J29: =LEFT(A29,3) -> 282 | K29: =LEFT(A29,4) -> 2829 | L29: =LEFT(A29,5) -> 28298 | M29: =LEFT(A29,1) -> 2
A30: 283110 | B30: AMORTS BATIMENT INDUSTRIELS | D30: 377645399 | F30: 57763368 | H30: 435408767 | I30: =LEFT(A30,2) -> 28 | J30: =LEFT(A30,3) -> 283 | K30: =LEFT(A30,4) -> 2831 | L30: =LEFT(A30,5) -> 28311 | M30: =LEFT(A30,1) -> 2
A31: 283410 | B31: AMORT AMENAG & INST TECH SOL PROPRE | F31: 13447119 | H31: 13447119 | I31: =LEFT(A31,2) -> 28 | J31: =LEFT(A31,3) -> 283 | K31: =LEFT(A31,4) -> 2834 | L31: =LEFT(A31,5) -> 28341 | M31: =LEFT(A31,1) -> 2
A32: 283510 | B32: AMORT DES AMENAG DE BUREAUX | D32: 65793499 | F32: 16124023 | H32: 81917522 | I32: =LEFT(A32,2) -> 28 | J32: =LEFT(A32,3) -> 283 | K32: =LEFT(A32,4) -> 2835 | L32: =LEFT(A32,5) -> 28351 | M32: =LEFT(A32,1) -> 2
A33: 283800 | B33: AMORTS AUTRES INSTAL & AGENCMENT | D33: 12861393 | F33: 1867731 | H33: 14729124 | I33: =LEFT(A33,2) -> 28 | J33: =LEFT(A33,3) -> 283 | K33: =LEFT(A33,4) -> 2838 | L33: =LEFT(A33,5) -> 28380 | M33: =LEFT(A33,1) -> 2
A34: 284110 | B34: AMORTS MAT ET OUTILS IND | D34: 297514034 | F34: 26814122 | H34: 324328156 | I34: =LEFT(A34,2) -> 28 | J34: =LEFT(A34,3) -> 284 | K34: =LEFT(A34,4) -> 2841 | L34: =LEFT(A34,5) -> 28411 | M34: =LEFT(A34,1) -> 2
A35: 284150 | B35: AMORT MAT DE COMMUNICATION | D35: 459713 | F35: 24620 | H35: 484333 | I35: =LEFT(A35,2) -> 28 | J35: =LEFT(A35,3) -> 284 | K35: =LEFT(A35,4) -> 2841 | L35: =LEFT(A35,5) -> 28415 | M35: =LEFT(A35,1) -> 2
A36: 284420 | B36: AMORT MATERIEL INFORMAIQUE | D36: 15998013 | F36: 2583580 | H36: 18581593 | I36: =LEFT(A36,2) -> 28 | J36: =LEFT(A36,3) -> 284 | K36: =LEFT(A36,4) -> 2844 | L36: =LEFT(A36,5) -> 28442 | M36: =LEFT(A36,1) -> 2
A37: 284440 | B37: AMORT MOBILIER DE BUREAU | D37: 4462000 | F37: 16667 | H37: 4478667 | I37: =LEFT(A37,2) -> 28 | J37: =LEFT(A37,3) -> 284 | K37: =LEFT(A37,4) -> 2844 | L37: =LEFT(A37,5) -> 28444 | M37: =LEFT(A37,1) -> 2
A38: 284500 | B38: AMORTS MATERIEL TRANSP | D38: 58423140 | F38: 4149241 | H38: 62572381 | I38: =LEFT(A38,2) -> 28 | J38: =LEFT(A38,3) -> 284 | K38: =LEFT(A38,4) -> 2845 | L38: =LEFT(A38,5) -> 28450 | M38: =LEFT(A38,1) -> 2
A39: 321000 | B39: STOCK POISSONS | C39: 365270359 | E39: 431895875 | F39: 365270359 | G39: 431895875 | I39: =LEFT(A39,2) -> 32 | J39: =LEFT(A39,3) -> 321 | K39: =LEFT(A39,4) -> 3210 | L39: =LEFT(A39,5) -> 32100 | M39: =LEFT(A39,1) -> 3
A40: 401000 | B40: Fr. FOURNISSEUR : MAREYEUR | E40: 4721812043 | F40: 4726300688 | H40: 4488645 | I40: =LEFT(A40,2) -> 40 | J40: =LEFT(A40,3) -> 401 | K40: =LEFT(A40,4) -> 4010 | L40: =LEFT(A40,5) -> 40100 | M40: =LEFT(A40,1) -> 4
...

Sheet Activités de l'entreprise R2
A1: Fiche R2
B4: Désignation de l'entreprise : | C4: ='Fiche de renseignement R1'!$J$4 -> 0
B5: Adresse de l'entreprise :
B6: ='Fiche de renseignement R1'!J7 -> 0 | L6: Sigle usuel : | M6: ='Fiche de renseignement R1'!AD7 -> 0
B7: N° d'identification : | L7: Exercice clos le :
B8: =+'Fiche de renseignement R1'!J10 -> 0 | K8: ='Fiche de renseignement R1'!V10 -> 0 | M8: Durée (en mois) | N8: ='Fiche de renseignement R1'!AH10 -> 12
A10: FICHE D'IDENTIFICATION ET RENSEIGNEMENTS DIVERS 2
L12: Contrôle de l'entreprise (cocher la case)
A14: ZK | B14: Forme juridique (1) | F14: 0 | G14: 2 | K14: ZQ | L14: Entreprise sous contrôle public
A16: ZL | B16: Régime fiscal (1) | F16: 2 | K16: ZR | L16: Entreprise sous contrôle privé national | Q16: X
A18: ZM | B18: Pays du siège social (1) | F18: 0 | G18: 7 | K18: ZS | L18: Entreprise sous contrôle privé étranger
A20: ZN | B20: Nbre d'établissements dans le pays | F20: 0 | G20: 1
A22: ZO | B22: Nbre d'établissements hors du pays | F22: 0 | G22: 0
B23: pour lesquels une comptabilité distincte est tenue
A25: ZP | B25: 1ère année exercice dans le pays | E25: 2 | F25: 0 | G25: 0 | H25: 1
A28: ACTIVITE DE L'ENTREPRISE
B30: DESIGNATION DE L'ACTIVITE (2) | C30: Code nomenclature d'activité (1) | K30: Valeur Ajoutée (VA) HT/ Chiffre d'affaire | M30: % activité dans le CA HT ou la VA
B33: TRAITEMENT ET EXPORTATION DE PRODUITS HALIEUTIQUES | D33: 3 | E33: 0 | F33: 0 | G33: 0 | H33: 2 | I33: 0 | L33: =IFERROR(VLOOKUP("702200",'BAL N'!A:H,8,FALSE),IFERROR(VLOOKUP(702200,'BAL N'!A:H,8,FALSE),0)) -> 5294648115 | M33: =IFERROR(+L33/$L$59,0) -> 1
M36: =IFERROR(+L36/$L$59,0) -> 0
M39: =IFERROR(+L39/$L$59,0) -> 0
M42: =IFERROR(+L42/$L$59,0) -> 0
M45: =IFERROR(+L45/$L$59,0) -> 0
M48: =IFERROR(+L48/$L$59,0) -> 0
M51: =IFERROR(+L51/$L$59,0) -> 0
M54: =IFERROR(+L54/$L$59,0) -> 0
B57: Divers
I59: TOTAL | L59: =SUM(L32:L56) -> 5294648115 | M59: =SUM(M32:M57) -> 1
B62: (1) Se réréfer aux tables des codes
B63: (2) Lister de manière précise les activités dans l'ordre décroissant du CAHT, ou de la valeur ajoutée (V.A.)
B64: (3) Rayer la mention inutile (utiliser de préférence la V.A.)

Sheet Dirigeants R3
A1: Fiche R3
A3: Désignation de l'entreprise | B3: ='Fiche de renseignement R1'!$J$4 -> 0
A4: Adresse de l'entreprise | B4: ='Activités de l''entreprise R2'!B6 -> 0 | D4: Sigle usuel | E4: ='Activités de l''entreprise R2'!M6 -> 0
A5: N° d'identification fiscale | B5: ='Activités de l''entreprise R2'!B8 -> 0 | C5: Exercice clos le | D5: ='Activités de l''entreprise R2'!K8 -> 0 | E5: Durée (en mois) | F5: ='Activités de l''entreprise R2'!N8 -> 12
A7: FICHE D'IDENTIFICATION ET RENSEIGNEMENTS DIVERS 3
A9: DIRIGEANTS (1)
A11: Nom | B11: Prénoms | C11: Qualité | D11: N° d'identification fiscale | E11: Adressse (BP, ville, pays)
A12: HDH | B12: HDDH | C12: HH | D12: DHD | E12: DHHH
A27: (1) Dirigeants = Président Directeur Général, Directeur Général, Adminsitrateur Général, Gérant, Autres.
A29: MEMBRES DU CONSEIL D'ADMINISTRATION
A31: Nom | B31: Prénoms | C31: Qualité | E31: Adressse (BP, ville, pays)

Sheet Tableau des Notes R4
A1: FICHE R4
A2: Désignation entité : | B2: ='Fiche de renseignement R1'!$J$4 -> 0 | D2: Excercice clos le : | E2: =+'Fiche de renseignement R1'!$V$10 -> 0
A3: Numéro d'identification : | B3: =+'Fiche de renseignement R1'!$J$10 -> 0 | D3: Durée en mois : | E3: =+'Fiche de renseignement R1'!$AH$10 -> 12
A6: FICHE RECAPITULATIVE DES NOTES ANNEXES PRESENTEES
A8: NOTES | B8: INTITULES | C8: A | E8: N/A
A9: NOTE 1 | B9: DETTES GARANTIES PAR DES SURETES REELLES
A10: NOTE 2 | B10: INFORMATIONS OBLIGATOIRES
A11: NOTE 3A | B11: IMMOBILISATION BRUTE
A12: NOTE 3B | B12: BIENS PRIS EN LOCATION ACQUISITION
A13: NOTE 3C | B13: IMMOBILISATIONS : AMORTISSEMENTS
A14: NOTE 3D | B14: IMMOBILISATIONS : PLUS-VALUES ET MOINS VALUES DE CESSION
A15: NOTE 3E | B15: INFORMATIONS SUR LES REEVALUATIONS EFFECTUEES PAR L'ENTITE
A16: NOTE 4 | B16: IMMOBILISATIONS FINANCIERES
A17: NOTE 5 | B17: ACTIF CIRCULANT HAO
A18: NOTE 6 | B18: STOCKS ET ENCOURS
A19: NOTE 7 | B19: CLIENTS PRODUITS A RECEVOIR
A20: NOTE 8 | B20: AUTRES CREANCES
... A54: NOTE 36 | B54: TABLES DES CODES

Sheet BILAN PAYSAGE
A1: BILAN PAYSAGE
A3: Désignation entité : | D3: ='Fiche de renseignement R1'!$J$4 -> 0 | I3: Excercice clos le : | J3: =+'Fiche de renseignement R1'!$V$10 -> 0
A4: Numéro d'identification : | D4: =+'Fiche de renseignement R1'!$J$10 -> 0 | I4: Durée en mois : | J4: =+'Fiche de renseignement R1'!$AH$10 -> 12
A6: REF | B6: ACTIF | C6: Note | D6: =IFERROR("Exercice au 31/12/"&YEAR('Fiche de renseignement R1'!V10),"Exercice au 31/12/N") -> Exercice au 31/12/1900 | G6: =IFERROR("Exercice au 31/12/"&YEAR('Fiche de renseignement R1'!Q20),"Exercice au 31/12/N-1") -> Exercice au 31/12/2020 | H6: REF | I6: PASSIF | J6: Note | K6: =IFERROR("Exercice au 31/12/"&YEAR('Fiche de renseignement R1'!V10),"Exercice au 31/12/N") -> Exercice au 31/12/1900 | L6: =IFERROR("Exercice au 31/12/"&YEAR('Fiche de renseignement R1'!Q20),"Exercice au 31/12/N-1") -> Exercice au 31/12/2020
D7: Brut | E7: Amorts et Dépréc. | F7: Net | G7: Net | K7: Net | L7: Net
A8: AD | B8: IMMOBILISATIONS INCORPORELLES | C8: 3 | D8: =+D9+D10+D11+D12 -> 0 | E8: =+E9+E10+E11+E12 -> 0 | F8: =+F9+F10+F11+F12 -> 0 | G8: =+G9+G10+G11+G12 -> 0 | H8: CA | I8: CAPITAL | J8: 13 | K8: =+SUMIF('BAL N'!J:J,"=101",'BAL N'!H:H)+SUMIF('BAL N'!J:J,"=102",'BAL N'!H:H)+SUMIF('BAL N'!J:J,"=103",'BAL N'!H:H)+SUMIF('BAL N'!J:J,"=104",'BAL N'!H:H) -> 145000000 | L8: =+SUMIF('BAL N'!J:J,"=101",'BAL N'!D:D)+SUMIF('BAL N'!J:J,"=102",'BAL N'!D:D)+SUMIF('BAL N'!J:J,"=103",'BAL N'!D:D)+SUMIF('BAL N'!J:J,"=104",'BAL N'!D:D) -> 145000000
A9: AE | B9: Frais de développement et de prospection | D9: =+SUMIF('BAL N'!J:J,"=211",'BAL N'!G:G)+SUMIF('BAL N'!K:K,"=2181",'BAL N'!G:G)+SUMIF('BAL N'!K:K,"=2191",'BAL N'!G:G) -> 0 | E9: =+SUMIF('BAL N'!K:K,"=2811",'BAL N'!H:H)+SUMIF('BAL N'!L:L,"=28181",'BAL N'!H:H)+SUMIF('BAL N'!L:L,"=28191",'BAL N'!H:H)+SUMIF('BAL N'!K:K,"=2911",'BAL N'!H:H)+SUMIF('BAL N'!K:K,"=2918",'BAL N'!H:H)+SUMIF('BAL N'!K:K,"=2919",'BAL N'!H:H) -> 0 | F9: =+D9-E9 -> 0 | G9: =+SUMIF('BAL N'!J:J,"=211",'BAL N'!C:C)+SUMIF('BAL N'!K:K,"=2181",'BAL N'!C:C)+SUMIF('BAL N'!K:K,"=2191",'BAL N'!C:C)-(SUMIF('BAL N'!K:K,"=2811",'BAL N'!D:D)+SUMIF('BAL N'!L:L,"=28181",'BAL N'!D:D)+SUMIF('BAL N'!L:L,"=28191",'BAL N'!D:D)+SUMIF('BAL N'!K:K,"=2911",'BAL N'!D:D)+SUMIF('BAL N'!K:K,"=2918",'BAL N'!D:D)+SUMIF('BAL N'!K:K,"=2919",'BAL N'!D:D)) -> 0 | H9: CB | I9: Apporteurs capital non appelé | J9: 13 | K9: =+SUMIF('BAL N'!J:J,"=109",'BAL N'!H:H) -> 0 | L9: =+SUMIF('BAL N'!J:J,"=109",'BAL N'!D:D) -> 0
A10: AF | B10: Brevets, licences, logiciels et droits similaires | D10: =+SUMIF('BAL N'!J:J,"=212",'BAL N'!G:G)+SUMIF('BAL N'!J:J,"=213",'BAL N'!G:G)+SUMIF('BAL N'!J:J,"=214",'BAL N'!G:G)+SUMIF('BAL N'!K:K,"=2193",'BAL N'!G:G) -> 0 | E10: =+SUMIF('BAL N'!K:K,"=2812",'BAL N'!H:H)+SUMIF('BAL N'!K:K,"=2813",'BAL N'!H:H)+SUMIF('BAL N'!K:K,"=2814",'BAL N'!H:H)+SUMIF('BAL N'!K:K,"=2912",'BAL N'!H:H)+SUMIF('BAL N'!K:K,"=2913",'BAL N'!H:H)+SUMIF('BAL N'!K:K,"=2914",'BAL N'!H:H)+SUMIF('BAL N'!K:K,"=2919",'BAL N'!H:H) -> 0 | F10: =+D10-E10 -> 0 | G10: =+SUMIF('BAL N'!J:J,"=212",'BAL N'!C:C)+SUMIF('BAL N'!J:J,"=213",'BAL N'!C:C)+SUMIF('BAL N'!J:J,"=214",'BAL N'!C:C)+SUMIF('BAL N'!K:K,"=2193",'BAL N'!C:C)-(SUMIF('BAL N'!K:K,"=2811",'BAL N'!D:D)+SUMIF('BAL N'!K:K,"=2812",'BAL N'!D:D)+SUMIF('BAL N'!K:K,"=2813",'BAL N'!D:D)+SUMIF('BAL N'!K:K,"=2814",'BAL N'!D:D)+SUMIF('BAL N'!L:L,"=28181",'BAL N'!D:D)+SUMIF('BAL N'!L:L,"=28191",'BAL N'!D:D)+SUMIF('BAL N'!K:K,"=2911",'BAL N'!D:D)+SUMIF('BAL N'!K:K,"=2912",'BAL N'!D:D)+SUMIF('BAL N'!K:K,"=2913",'BAL N'!D:D)+SUMIF('BAL N'!K:K,"=2914",'BAL N'!D:D)+SUMIF('BAL N'!K:K,"=2918",'BAL N'!D:D)+SUMIF('BAL N'!K:K,"=2919",'BAL N'!D:D)) -> 0 | H10: CD | I10: Primes liées au capital social | J10: 14 | K10: =+SUMIF('BAL N'!J:J,"=105",'BAL N'!H:H) -> 0 | L10: =+SUMIF('BAL N'!J:J,"=105",'BAL N'!D:D) -> 0
A11: AG | B11: Fonds commercial et droit au bail | D11: =+SUMIF('BAL N'!J:J,"=215",'BAL N'!G:G)+SUMIF('BAL N'!J:J,"=216",'BAL N'!G:G) -> 0 | E11: =+SUMIF('BAL N'!K:K,"=2815",'BAL N'!H:H)+SUMIF('BAL N'!K:K,"=2816",'BAL N'!H:H)+SUMIF('BAL N'!K:K,"=2915",'BAL N'!H:H)+SUMIF('BAL N'!K:K,"=2916",'BAL N'!H:H) -> 0 | F11: =+D11-E11 -> 0 | G11: =+SUMIF('BAL N'!J:J,"=215",'BAL N'!C:C)+SUMIF('BAL N'!J:J,"=216",'BAL N'!C:C)-(SUMIF('BAL N'!K:K,"=2815",'BAL N'!D:D)+SUMIF('BAL N'!K:K,"=2816",'BAL N'!D:D)+SUMIF('BAL N'!K:K,"=2915",'BAL N'!D:D)+SUMIF('BAL N'!K:K,"=2916",'BAL N'!D:D)) -> 0 | H11: CE | I11: Ecarts de réévaluation | J11: 3e | K11: =+SUMIF('BAL N'!J:J,"=106",'BAL N'!H:H) -> 0 | L11: =+SUMIF('BAL N'!J:J,"=106",'BAL N'!D:D) -> 0
A12: AH | B12: Autres immobilisations incorporelles | D12: =+SUMIF('BAL N'!J:J,"=217",'BAL N'!G:G)+SUMIF('BAL N'!J:J,"=218",'BAL N'!G:G)-SUMIF('BAL N'!K:K,"=2181",'BAL N'!G:G)+SUMIF('BAL N'!K:K,"=2198",'BAL N'!G:G) -> 0 | E12: =+SUMIF('BAL N'!K:K,"=2817",'BAL N'!H:H)+SUMIF('BAL N'!K:K,"=2818",'BAL N'!H:H)+SUMIF('BAL N'!K:K,"=2917",'BAL N'!H:H)+SUMIF('BAL N'!K:K,"=2918",'BAL N'!H:H)+SUMIF('BAL N'!K:K,"=2919",'BAL N'!H:H) -> 0 | F12: =+D12-E12 -> 0 | G12: =+SUMIF('BAL N'!J:J,"=217",'BAL N'!C:C)+SUMIF('BAL N'!J:J,"=218",'BAL N'!C:C)-SUMIF('BAL N'!K:K,"=2181",'BAL N'!C:C)+SUMIF('BAL N'!K:K,"=2198",'BAL N'!C:C)-(SUMIF('BAL N'!K:K,"=2817",'BAL N'!D:D)+SUMIF('BAL N'!K:K,"=2818",'BAL N'!D:D)+SUMIF('BAL N'!K:K,"=2917",'BAL N'!D:D)+SUMIF('BAL N'!K:K,"=2918",'BAL N'!D:D)+SUMIF('BAL N'!K:K,"=2919",'BAL N'!D:D)) -> 0 | H12: CF | I12: Réserves indisponibles | J12: 14 | K12: =+SUMIF('BAL N'!J:J,"=111",'BAL N'!H:H)+SUMIF('BAL N'!J:J,"=112",'BAL N'!H:H)+SUMIF('BAL N'!J:J,"=113",'BAL N'!H:H) -> 200000 | L12: =+SUMIF('BAL N'!J:J,"=111",'BAL N'!D:D)+SUMIF('BAL N'!J:J,"=112",'BAL N'!D:D)+SUMIF('BAL N'!J:J,"=113",'BAL N'!D:D) -> 200000
A13: AI | B13: IMMOBILISATIONS CORPORELLES | C13: 3 | D13: =SUM(D14:D19) -> 2269201127 | E13: =SUM(E14:E19) -> 833237141 | F13: =SUM(F14:F19) -> 1435963986 | G13: =SUM(G14:G19) -> 1416348561 | H13: CG | I13: Réserves libres | J13: 14 | K13: =+SUMIF('BAL N'!J:J,"=118",'BAL N'!H:H) -> 118365583 | L13: =+SUMIF('BAL N'!J:J,"=118",'BAL N'!D:D) -> 118365583
A14: AJ | B14: Terrains (1) (1) dont placement en net ………../………… | D14: =+SUMIF('BAL N'!I:I,"=22",'BAL N'!G:G) -> 147669000 | E14: =+SUMIF('BAL N'!J:J,"=282",'BAL N'!H:H)+SUMIF('BAL N'!J:J,"=292",'BAL N'!H:H) -> 79950 | F14: =+D14-E14 -> 147589050 | G14: =+SUMIF('BAL N'!I:I,"=22",'BAL N'!C:C)-(SUMIF('BAL N'!J:J,"=282",'BAL N'!D:D)+SUMIF('BAL N'!J:J,"=292",'BAL N'!D:D)) -> 56669000 | H14: CH | I14: Report à nouveau (+ ou -) | J14: 14 | K14: =+SUMIF('BAL N'!I:I,"=12",'BAL N'!H:H)-SUMIF('BAL N'!I:I,"=12",'BAL N'!G:G) -> 0 | L14: =+SUMIF('BAL N'!I:I,"=13",'BAL N'!D:D)-SUMIF('BAL N'!I:I,"=13",'BAL N'!C:C) -> 892752843
A15: AK | B15: Bâtiments (1) dont placement en net ………../………… | D15: =+SUMIF('BAL N'!J:J,"=231",'BAL N'!G:G)+SUMIF('BAL N'!J:J,"=232",'BAL N'!G:G)+SUMIF('BAL N'!J:J,"=233",'BAL N'!G:G)+SUMIF('BAL N'!J:J,"=237",'BAL N'!G:G)+SUMIF('BAL N'!K:K,"=2391",'BAL N'!G:G) -> 1101670826 | E15: =+SUMIF('BAL N'!K:K,"=2831",'BAL N'!H:H)+SUMIF('BAL N'!K:K,"=2832",'BAL N'!H:H)+SUMIF('BAL N'!K:K,"=2833",'BAL N'!H:H)+SUMIF('BAL N'!K:K,"=2837",'BAL N'!H:H)+SUMIF('BAL N'!K:K,"=2931",'BAL N'!H:H)+SUMIF('BAL N'!K:K,"=2932",'BAL N'!H:H)+SUMIF('BAL N'!K:K,"=2933",'BAL N'!H:H)+SUMIF('BAL N'!K:K,"=2937",'BAL N'!H:H)+SUMIF('BAL N'!K:K,"=2939",'BAL N'!H:H) -> 262184384 | F15: =+D15-E15 -> 839486442 | G15: =+SUMIF('BAL N'!J:J,"=231",'BAL N'!C:C)+SUMIF('BAL N'!J:J,"=232",'BAL N'!C:C)+SUMIF('BAL N'!J:J,"=233",'BAL N'!C:C)+SUMIF('BAL N'!J:J,"=237",'BAL N'!C:C)++SUMIF('BAL N'!J:J,"=239",'BAL N'!C:C)-SUMIF('BAL N'!J:J,"=238",'BAL N'!D:D)-(SUMIF('BAL N'!K:K,"=2831",'BAL N'!D:D)+SUMIF('BAL N'!K:K,"=2832",'BAL N'!D:D)+SUMIF('BAL N'!K:K,"=2833",'BAL N'!D:D)+SUMIF('BAL N'!K:K,"=2837",'BAL N'!D:D)+SUMIF('BAL N'!K:K,"=2931",'BAL N'!D:D)+SUMIF('BAL N'!K:K,"=2932",'BAL N'!D:D)+SUMIF('BAL N'!K:K,"=2933",'BAL N'!D:D)+SUMIF('BAL N'!K:K,"=2937",'BAL N'!D:D)+SUMIF('BAL N'!K:K,"=2939",'BAL N'!D:D)) -> 894569983 | H15: CJ | I15: Résutat net de l'exercice (bénéfice + ou perte -) | K15: =+SUMIF('BAL N'!M:M,"=7",'BAL N'!H:H)+SUMIF('BAL N'!M:M,"=8",'BAL N'!H:H)-SUMIF('BAL N'!M:M,"=6",'BAL N'!G:G)-SUMIF('BAL N'!M:M,"=8",'BAL N'!G:G)+SUMIF('BAL N'!J:J,"=603",'BAL N'!H:H) -> 87524556 | L15: =-SUMIF('BAL N'!J:J,"=131",'BAL N'!C:C)+SUMIF('BAL N'!J:J,"=131",'BAL N'!D:D) -> 0
A16: AL | B16: Aménagements, agencements et installations | D16: =+SUMIF('BAL N'!J:J,"=234",'BAL N'!G:G)+SUMIF('BAL N'!J:J,"=235",'BAL N'!G:G)+SUMIF('BAL N'!J:J,"=238",'BAL N'!G:G)+SUMIF('BAL N'!J:J,"=239",'BAL N'!G:G) -> 500771393 | E16: =+SUMIF('BAL N'!K:K,"=2834",'BAL N'!H:H)+SUMIF('BAL N'!K:K,"=2835",'BAL N'!H:H)+SUMIF('BAL N'!K:K,"=2838",'BAL N'!H:H)+SUMIF('BAL N'!K:K,"=2934",'BAL N'!H:H)+SUMIF('BAL N'!K:K,"=2935",'BAL N'!H:H)+SUMIF('BAL N'!K:K,"=2938",'BAL N'!H:H)+SUMIF('BAL N'!K:K,"=2939",'BAL N'!H:H) -> 194115907 | F16: =+D16-E16 -> 306655486 | G16: =+SUMIF('BAL N'!J:J,"=234",'BAL N'!C:C)+SUMIF('BAL N'!J:J,"=235",'BAL N'!C:C)+SUMIF('BAL N'!J:J,"=238",'BAL N'!C:C)+SUMIF('BAL N'!K:K,"=2392",'BAL N'!C:C)+SUMIF('BAL N'!K:K,"=2393",'BAL N'!C:C)-(+SUMIF('BAL N'!K:K,"=2834",'BAL N'!D:D)+SUMIF('BAL N'!K:K,"=2835",'BAL N'!D:D)+SUMIF('BAL N'!K:K,"=2838",'BAL N'!D:D)+SUMIF('BAL N'!K:K,"=2934",'BAL N'!D:D)+SUMIF('BAL N'!K:K,"=2935",'BAL N'!D:D)+SUMIF('BAL N'!K:K,"=2938",'BAL N'!D:D)+SUMIF('BAL N'!K:K,"=2939",'BAL N'!D:D)) -> 275817542 | H16: CL | I16: Subventions d'investissement | J16: 15 | K16: =+SUMIF('BAL N'!I:I,"=14",'BAL N'!H:H) -> 0 | L16: =+SUMIF('BAL N'!I:I,"=14",'BAL N'!D:D) -> 0
A17: AM | B17: Matériel, mobilier et actifs biologiques | D17: =+SUMIF('BAL N'!I:I,"=24",'BAL N'!G:G)-SUMIF('BAL N'!J:J,"=245",'BAL N'!G:G)-SUMIF('BAL N'!K:K,"=2495",'BAL N'!G:G) -> 453821027 | E17: =+SUMIF('BAL N'!J:J,"=284",'BAL N'!H:H)-SUMIF('BAL N'!K:K,"=2845",'BAL N'!H:H)+SUMIF('BAL N'!J:J,"=294",'BAL N'!H:H)-SUMIF('BAL N'!K:K,"=2945",'BAL N'!H:H)-SUMIF('BAL N'!K:K,"=2949",'BAL N'!H:H) -> 318433760 | F17: =+D17-E17 -> 135387267 | G17: =+SUMIF('BAL N'!I:I,"=24",'BAL N'!C:C)-SUMIF('BAL N'!J:J,"=245",'BAL N'!C:C)-SUMIF('BAL N'!J:J,"=2495",'BAL N'!C:C)-(SUMIF('BAL N'!J:J,"=284",'BAL N'!D:D)-SUMIF('BAL N'!K:K,"=2845",'BAL N'!D:D)+SUMIF('BAL N'!J:J,"=294",'BAL N'!D:D)-SUMIF('BAL N'!K:K,"=2945",'BAL N'!D:D)-SUMIF('BAL N'!K:K,"=2949",'BAL N'!D:D)) -> 170152519 | H17: CM | I17: Provisions réglementées et fonds assimilés | J17: 15 | K17: =+SUMIF('BAL N'!I:I,"=15",'BAL N'!H:H) -> 0 | L17: =+SUMIF('BAL N'!I:I,"=15",'BAL N'!D:D) -> 0
A18: AN | B18: Matériel de transport | D18: =+SUMIF('BAL N'!J:J,"=245",'BAL N'!G:G)+SUMIF('BAL N'!K:K,"=2495",'BAL N'!G:G) -> 65268881 | E18: =+SUMIF('BAL N'!K:K,"=2845",'BAL N'!H:H)+SUMIF('BAL N'!K:K,"=2849",'BAL N'!H:H)+SUMIF('BAL N'!K:K,"=2945",'BAL N'!H:H) -> 58423140 | F18: =+D18-E18 -> 6845741 | G18: =+SUMIF('BAL N'!J:J,"=245",'BAL N'!C:C)+SUMIF('BAL N'!K:K,"=2495",'BAL N'!C:C)-(+SUMIF('BAL N'!K:K,"=2845",'BAL N'!D:D)+SUMIF('BAL N'!K:K,"=2849",'BAL N'!D:D)+SUMIF('BAL N'!K:K,"=2945",'BAL N'!D:D)) -> 19139517 | H18: CP | I18: TOTAL CAPITAUX PROPRES ET RESSOURCES ASSIMILEES | K18: =SUM(K8:K17) -> 351090139 | L18: =SUM(L8:L17) -> 1156318426
A19: AP | B19: Avances & acomptes versés sur immobilisations | C19: 3 | D19: =+SUMIF('BAL N'!I:I,"=25",'BAL N'!G:G) -> 0 | E19: =+SUMIF('BAL N'!J:J,"=295",'BAL N'!H:H) -> 0 | F19: =+D19-E19 -> 0 | G19: =+SUMIF('BAL N'!I:I,"=25",'BAL N'!C:C)-SUMIF('BAL N'!J:J,"=295",'BAL N'!D:D) -> 0 | H19: DA | I19: Emprunts et dettes financières diverses | J19: 16 | K19: =+SUMIF('BAL N'!I:I,"=16",'BAL N'!H:H)+SUMIF('BAL N'!J:J,"=181",'BAL N'!H:H)+SUMIF('BAL N'!J:J,"=182",'BAL N'!H:H)+SUMIF('BAL N'!J:J,"=184",'BAL N'!H:H) -> 0 | L19: =+SUMIF('BAL N'!I:I,"=16",'BAL N'!D:D)+SUMIF('BAL N'!J:J,"=181",'BAL N'!D:D)+SUMIF('BAL N'!J:J,"=182",'BAL N'!D:D)+SUMIF('BAL N'!J:J,"=183",'BAL N'!D:D)+SUMIF('BAL N'!J:J,"=184",'BAL N'!D:D) -> 0
A20: AQ | B20: IMMOBILISATIONS FINANCIERES | C20: 4 | D20: =SUM(D21:D22) -> 12180480 | E20: =SUM(E21:E22) -> 0 | F20: =SUM(F21:F22) -> 12180480 | G20: =SUM(G21:G22) -> 12180480 | H20: DB | I20: Dettes de location acquisition | J20: 16 | K20: =+SUMIF('BAL N'!I:I,"=17",'BAL N'!H:H) -> 0 | L20: =+SUMIF('BAL N'!I:I,"=17",'BAL N'!D:D) -> 0
A21: AR | B21: Titres de participation | D21: =+SUMIF('BAL N'!I:I,"=26",'BAL N'!G:G) -> 0 | E21: =+SUMIF('BAL N'!J:J,"=296",'BAL N'!H:H) -> 0 | F21: =+D21-E21 -> 0 | G21: =+SUMIF('BAL N'!I:I,"=26",'BAL N'!C:C)-SUMIF('BAL N'!J:J,"=296",'BAL N'!D:D) -> 0 | H21: DC | I21: Provisions pour risques et charges | J21: 16 | K21: =+SUMIF('BAL N'!I:I,"=19",'BAL N'!H:H) -> 0 | L21: =+SUMIF('BAL N'!I:I,"=19",'BAL N'!D:D) -> 0
A22: AS | B22: Autres immobilisations financières | D22: =+SUMIF('BAL N'!I:I,"=27",'BAL N'!G:G) -> 12180480 | E22: =+SUMIF('BAL N'!J:J,"=297",'BAL N'!H:H) -> 0 | F22: =+D22-E22 -> 12180480 | G22: =+SUMIF('BAL N'!I:I,"=27",'BAL N'!C:C)-SUMIF('BAL N'!J:J,"=297",'BAL N'!D:D) -> 12180480 | H22: DD | I22: TOTAL DETTES FINANCIERES ET RESSOURCES ASSIMILEES | K22: =SUM(K19:K21) -> 0 | L22: =SUM(L19:L21) -> 0
A23: AZ | B23: TOTAL ACTIF IMMOBILISE | D23: =+D20+D13+D8 -> 2281381607 | E23: =+E20+E13+E8 -> 833237141 | F23: =+F20+F13+F8 -> 1448144466 | G23: =+G20+G13+G8 -> 1428529041 | H23: DF | I23: TOTAL RESSOURCES STABLES
A24: BA | B24: ACTIF CIRCULANT H.A.O. | C24: 5 | D24: =+SUMIF('BAL N'!J:J,"=485",'BAL N'!G:G)+SUMIF('BAL N'!J:J,"=488",'BAL N'!G:G) -> 0 | E24: =+SUMIF('BAL N'!J:J,"=498",'BAL N'!H:H) -> 0 | F24: =+D24-E24 -> 0 | G24: =+SUMIF('BAL N'!J:J,"=485",'BAL N'!C:C)+SUMIF('BAL N'!J:J,"=488",'BAL N'!C:C)-SUMIF('BAL N'!J:J,"=498",'BAL N'!D:D) -> 0 | H24: DH | I24: Dettes circulantes HAO | J24: 5 | K24: =+SUMIF('BAL N'!J:J,"=481",'BAL N'!H:H)+SUMIF('BAL N'!J:J,"=482",'BAL N'!H:H)+SUMIF('BAL N'!J:J,"=484",'BAL N'!H:H)+SUMIF('BAL N'!K:K,"=4998",'BAL N'!H:H) -> 0 | L24: =+SUMIF('BAL N'!J:J,"=481",'BAL N'!D:D)+SUMIF('BAL N'!J:J,"=482",'BAL N'!D:D)+SUMIF('BAL N'!J:J,"=484",'BAL N'!D:D)+SUMIF('BAL N'!K:K,"=4998",'BAL N'!D:D) -> 0
A25: BB | B25: STOCKS ET ENCOURS | C25: 6 | D25: =+SUMIF('BAL N'!I:I,"=31",'BAL N'!G:G)+SUMIF('BAL N'!I:I,"=32",'BAL N'!G:G)+SUMIF('BAL N'!I:I,"=33",'BAL N'!G:G)+SUMIF('BAL N'!I:I,"=34",'BAL N'!G:G)+SUMIF('BAL N'!I:I,"=35",'BAL N'!G:G)+SUMIF('BAL N'!I:I,"=36",'BAL N'!G:G)+SUMIF('BAL N'!I:I,"=37",'BAL N'!G:G)+SUMIF('BAL N'!I:I,"=38",'BAL N'!G:G) -> 365270359 | E25: =+SUMIF('BAL N'!I:I,"=39",'BAL N'!H:H) -> 0 | F25: =+D25-E25 -> 365270359 | G25: =+SUMIF('BAL N'!I:I,"=31",'BAL N'!C:C)+SUMIF('BAL N'!I:I,"=32",'BAL N'!C:C)+SUMIF('BAL N'!I:I,"=33",'BAL N'!C:C)+SUMIF('BAL N'!I:I,"=34",'BAL N'!C:C)+SUMIF('BAL N'!I:I,"=35",'BAL N'!C:C)+SUMIF('BAL N'!I:I,"=36",'BAL N'!C:C)+SUMIF('BAL N'!I:I,"=37",'BAL N'!C:C)+SUMIF('BAL N'!I:I,"=38",'BAL N'!C:C)-SUMIF('BAL N'!I:I,"=39",'BAL N'!D:D) -> 433749204 | H25: DI | I25: Clients, avances reçues | J25: 7 | K25: =+SUMIF('BAL N'!J:J,"=419",'BAL N'!H:H) -> 34387691773 | L25: =+SUMIF('BAL N'!J:J,"=419",'BAL N'!D:D) -> 29055421827
A26: BG | B26: CREANCES ET EMPLOIS ASSIMILES | F26: =+D26-E26 -> 0 | H26: DJ | I26: Fournisseurs d'exploitation | J26: 17 | K26: =+SUMIF('BAL N'!I:I,"=40",'BAL N'!H:H)-SUMIF('BAL N'!J:J,"=409",'BAL N'!H:H) -> 3938800 | L26: =+SUMIF('BAL N'!J:J,"=401",'BAL N'!D:D)+SUMIF('BAL N'!J:J,"=402",'BAL N'!D:D)+SUMIF('BAL N'!J:J,"=408",'BAL N'!D:D)-SUMIF('BAL N'!J:J,"=401",'BAL N'!C:C) -> 12004500
A27: BH | B27: Fournisseurs, avances versées | C27: 17 | D27: =+SUMIF('BAL N'!I:I,"=40",'BAL N'!G:G)-SUMIF('BAL N'!J:J,"=490",'BAL N'!D:D) -> 130837030 | E27: =+SUMIF('BAL N'!J:J,"=490",'BAL N'!H:H) -> 0 | F27: =+D27-E27 -> 130837030 | G27: =+SUMIF('BAL N'!I:I,"=40",'BAL N'!C:C)-SUMIF('BAL N'!J:J,"=490",'BAL N'!D:D)-SUMIF('BAL N'!J:J,"409",'BAL N'!D:D) -> 7010266011 | H27: DK | I27: Dettes fiscales et sociales | J27: 18 | K27: =+SUMIF('BAL N'!I:I,"=42",'BAL N'!H:H)+SUMIF('BAL N'!I:I,"=43",'BAL N'!H:H)+SUMIF('BAL N'!I:I,"=44",'BAL N'!H:H) -> 21104751 | L27: =+SUMIF('BAL N'!I:I,"=42",'BAL N'!D:D)-SUMIF('BAL N'!J:J,"=421",'BAL N'!D:D)+SUMIF('BAL N'!K:K,"=4287",'BAL N'!D:D)+SUMIF('BAL N'!I:I,"=43",'BAL N'!D:D)-SUMIF('BAL N'!K:K,"=4387",'BAL N'!D:D)+SUMIF('BAL N'!J:J,"=441",'BAL N'!D:D)+SUMIF('BAL N'!J:J,"=442",'BAL N'!D:D)+SUMIF('BAL N'!J:J,"=443",'BAL N'!D:D)+SUMIF('BAL N'!K:K,"=4441",'BAL N'!D:D)+SUMIF('BAL N'!J:J,"=446",'BAL N'!D:D)+SUMIF('BAL N'!J:J,"=447",'BAL N'!D:D)+SUMIF('BAL N'!K:K,"=4486",'BAL N'!D:D)+SUMIF('BAL N'!K:K,"=4494",'BAL N'!D:D) -> 27035439
A28: BI | B28: Clients | C28: 7 | D28: =+SUMIF('BAL N'!I:I,"=41",'BAL N'!G:G)-SUMIF('BAL N'!J:J,"=419",'BAL N'!G:G) -> 33496906640 | E28: =+SUMIF('BAL N'!J:J,"=491",'BAL N'!H:H) -> 0 | F28: =+D28-E28 -> 33496906640 | G28: =+SUMIF('BAL N'!I:I,"=41",'BAL N'!C:C)-SUMIF('BAL N'!J:J,"=491",'BAL N'!D:D)-SUMIF('BAL N'!J:J,"=411",'BAL N'!D:D) -> 28202318525 | H28: DM | I28: Autres dettes | J28: 19 | K28: =+SUMIF('BAL N'!J:J,"=185",'BAL N'!H:H)+SUMIF('BAL N'!I:I,"=45",'BAL N'!H:H)+SUMIF('BAL N'!I:I,"=47",'BAL N'!H:H)+SUMIF('BAL N'!I:I,"=46",'BAL N'!H:H)-SUMIF('BAL N'!J:J,"=479",'BAL N'!H:H) -> 30374167 | L28: =+SUMIF('BAL N'!J:J,"=185",'BAL N'!D:D)+SUMIF('BAL N'!K:K,"=4712",'BAL N'!D:D)+SUMIF('BAL N'!J:J,"=472",'BAL N'!D:D)+SUMIF('BAL N'!J:J,"=477",'BAL N'!D:D)+SUMIF('BAL N'!I:I,"=46",'BAL N'!D:D)-SUMIF('BAL N'!J:J,"=4712",'BAL N'!C:C) -> 30374167
A29: BJ | B29: Autres créances | C29: 8 | D29: =SUMIF('BAL N'!J:J,"=185",'BAL N'!G:G)+SUMIF('BAL N'!I:I,"=42",'BAL N'!G:G)+SUMIF('BAL N'!I:I,"=43",'BAL N'!G:G)+SUMIF('BAL N'!I:I,"=44",'BAL N'!G:G)+SUMIF('BAL N'!I:I,"=45",'BAL N'!G:G)+SUMIF('BAL N'!I:I,"=46",'BAL N'!G:G)+SUMIF('BAL N'!I:I,"=47",'BAL N'!G:G)-SUMIF('BAL N'!J:J,"=478",'BAL N'!G:G) -> 24841088 | E29: =+SUMIF('BAL N'!J:J,"=492",'BAL N'!H:H)+SUMIF('BAL N'!J:J,"=493",'BAL N'!H:H)+SUMIF('BAL N'!J:J,"=494",'BAL N'!H:H)+SUMIF('BAL N'!J:J,"=495",'BAL N'!H:H)+SUMIF('BAL N'!J:J,"=496",'BAL N'!H:H)+SUMIF('BAL N'!J:J,"=497",'BAL N'!H:H) -> 0 | F29: =+D29-E29 -> 24841088 | G29: =+SUMIF('BAL N'!K:K,"=4287",'BAL N'!C:C)+SUMIF('BAL N'!K:K,"=4387",'BAL N'!C:C)+SUMIF('BAL N'!K:K,"=4449",'BAL N'!C:C)+SUMIF('BAL N'!J:J,"=421",'BAL N'!C:C)+SUMIF('BAL N'!J:J,"=445",'BAL N'!C:C)+SUMIF('BAL N'!K:K,"=4487",'BAL N'!C:C)+SUMIF('BAL N'!J:J,"=449",'BAL N'!C:C)+SUMIF('BAL N'!I:I,"=45",'BAL N'!C:C)+SUMIF('BAL N'!I:I,"=46",'BAL N'!C:C)+SUMIF('BAL N'!K:K,"=4711",'BAL N'!C:C)+SUMIF('BAL N'!J:J,"=475",'BAL N'!C:C)+SUMIF('BAL N'!J:J,"=476",'BAL N'!C:C)-(SUMIF('BAL N'!J:J,"=492",'BAL N'!D:D)+SUMIF('BAL N'!J:J,"=493",'BAL N'!D:D)+SUMIF('BAL N'!J:J,"=495",'BAL N'!D:D)+SUMIF('BAL N'!J:J,"=496",'BAL N'!D:D)+SUMIF('BAL N'!J:J,"=497",'BAL N'!D:D))-SUMIF('BAL N'!K:K,"=4711",'BAL N'!D:D) -> 36121455 | H29: DN | I29: Provisions pour risques à court terme | J29: 19 | K29: =+SUMIF('BAL N'!J:J,"=499",'BAL N'!H:H)+SUMIF('BAL N'!J:J,"=599",'BAL N'!H:H)-SUMIF('BAL N'!K:K,"=4998",'BAL N'!H:H) -> 0 | L29: =+SUMIF('BAL N'!J:J,"=499",'BAL N'!D:D)+SUMIF('BAL N'!J:J,"=599",'BAL N'!D:D)-SUMIF('BAL N'!K:K,"=4998",'BAL N'!D:D) -> 0
A30: BK | B30: TOTAL ACTIF CIRCULANT | D30: =SUM(D24:D29) -> 34017855117 | E30: =SUM(E24:E29) -> 0 | F30: =SUM(F24:F29) -> 34017855117 | G30: =SUM(G24:G29) -> 35682455195 | H30: DP | I30: TOTAL PASSIF CIRCULANT | K30: =SUM(K24:K29) -> 34443109491 | L30: =SUM(L24:L29) -> 29124835933
A31: BQ | B31: Titres de placement | C31: 9 | D31: =+SUMIF('BAL N'!I:I,"=50",'BAL N'!G:G) -> 0 | E31: =+SUMIF('BAL N'!J:J,"=590",'BAL N'!H:H) -> 0 | F31: =+D31-E31 -> 0 | G31: =+SUMIF('BAL N'!I:I,"=59",'BAL N'!C:C)-SUMIF('BAL N'!J:J,"=590",'BAL N'!D:D) -> 0
A32: BR | B32: Valeurs à encaisser | C32: 10 | D32: =+SUMIF('BAL N'!I:I,"=51",'BAL N'!G:G) -> 0 | E32: =+SUMIF('BAL N'!J:J,"=591",'BAL N'!H:H) -> 0 | F32: =+D32-E32 -> 0 | G32: =+SUMIF('BAL N'!I:I,"=51",'BAL N'!C:C)-SUMIF('BAL N'!J:J,"=591",'BAL N'!D:D) -> 0 | H32: DQ | I32: Banques, crédits d'escompte | J32: 20 | K32: =+SUMIF('BAL N'!J:J,"=564",'BAL N'!H:H)+SUMIF('BAL N'!J:J,"=565",'BAL N'!H:H) -> 0 | L32: =+SUMIF('BAL N'!J:J,"=564",'BAL N'!D:D)+SUMIF('BAL N'!J:J,"=565",'BAL N'!D:D) -> 0
A33: BS | B33: Banques, chèques postaux, caisse et assimilés | C33: 11 | D33: =SUMIF('BAL N'!I:I,"=52",'BAL N'!G:G)+SUMIF('BAL N'!I:I,"=53",'BAL N'!G:G)+SUMIF('BAL N'!I:I,"=54",'BAL N'!G:G)+SUMIF('BAL N'!I:I,"=55",'BAL N'!G:G)+SUMIF('BAL N'!I:I,"=57",'BAL N'!G:G)+SUMIF('BAL N'!J:J,"=581",'BAL N'!G:G)+SUMIF('BAL N'!J:J,"=582",'BAL N'!G:G) -> 220952890 | E33: =+SUMIF('BAL N'!J:J,"=592",'BAL N'!H:H)+SUMIF('BAL N'!J:J,"=593",'BAL N'!H:H)+SUMIF('BAL N'!J:J,"=594",'BAL N'!H:H) -> 0 | F33: =+D33-E33 -> 220952890 | G33: =SUMIF('BAL N'!I:I,"=52",'BAL N'!C:C)+SUMIF('BAL N'!I:I,"=57",'BAL N'!C:C)+SUMIF('BAL N'!I:I,"=58",'BAL N'!C:C)+SUMIF('BAL N'!I:I,"=55",'BAL N'!C:C)+SUMIF('BAL N'!I:I,"=54",'BAL N'!C:C)+SUMIF('BAL N'!I:I,"=53",'BAL N'!C:C)-SUMIF('BAL N'!J:J,"=592",'BAL N'!D:D) -> 92418291 | H33: DR | I33: Banques, établissements financiers et crédits de trésorerie | J33: 20 | K33: =+SUMIF('BAL N'!I:I,"=52",'BAL N'!H:H)+SUMIF('BAL N'!I:I,"=53",'BAL N'!H:H)+SUMIF('BAL N'!J:J,"=561",'BAL N'!H:H)+SUMIF('BAL N'!J:J,"=566",'BAL N'!H:H) -> 0 | L33: =+SUMIF('BAL N'!I:I,"=52",'BAL N'!D:D)+SUMIF('BAL N'!J:J,"=561",'BAL N'!D:D)+SUMIF('BAL N'!J:J,"=566",'BAL N'!D:D) -> 0
A34: BT | B34: TOTAL TRESORERIE - ACTIF | D34: =SUM(D31:D33) -> 220952890 | E34: =SUM(E31:E33) -> 0 | F34: =SUM(F31:F33) -> 220952890 | G34: =SUM(G31:G33) -> 92418291 | H34: DT | I34: TOTAL TRESORERIE - PASSIF | K34: =+K32+K33 -> 0 | L34: =+L32+L33 -> 0
A35: BU | B35: Ecarts de conversion - Actif | C35: 12 | D35: =+SUMIF('BAL N'!J:J,"=478",'BAL N'!G:G) -> 0 | G35: =+SUMIF('BAL N'!J:J,"=478",'BAL N'!C:C) -> 0 | H35: DV | I35: Ecarts de conversion - Passif | J35: 12 | K35: =+SUMIF('BAL N'!J:J,"=479",'BAL N'!H:H) -> 0 | L35: =+SUMIF('BAL N'!J:J,"=479",'BAL N'!D:D) -> 0
A36: BZ | B36: TOTAL GENERAL | D36: =+D34+D30+D23 -> 36520189614 | E36: =+E34+E30+E23 -> 833237141 | F36: =+F34+F30+F23 -> 35686952473 | G36: =+G34+G30+G23 -> 37203402527 | H36: DZ | I36: TOTAL GENERAL | K36: =+K34+K30+K22+K18 -> 34794199630 | L36: =+L34+L30+L22+L18 -> 30281154359

Sheet COMPTE DE RESULTAT
A1: COMPTE DE RESULTAT
A3: Désignation entité : | B3: ='Fiche de renseignement R1'!$J$4 -> 0 | D3: Excercice clos le : | E3: =+'Fiche de renseignement R1'!$V$10 -> 0
A4: Numéro d'identification : | B4: =+'Fiche de renseignement R1'!$J$10 -> 0 | D4: Durée en mois : | E4: =+'Fiche de renseignement R1'!$AH$10 -> 12
A6: REF | B6: LIBELLES | D6: NOTE | E6: =IFERROR("31/12/"&YEAR('Fiche de renseignement R1'!V10),"Exercice au 31/12/N") -> 31/12/1900 | F6: =IFERROR("31/12/"&YEAR('Fiche de renseignement R1'!Q20),"Exercice au 31/12/N-1") -> 31/12/2020
A7: TA | B7: Ventes de marchandises A | C7: + | D7: 21 | E7: =+SUMIF('BAL N'!J:J,"=701",'BAL N'!H:H) -> 0 | F7: =+SUMIF('BAL N-1'!J:J,"=701",'BAL N-1'!H:H) -> 0
A8: RA | B8: Achats de marchandises | C8: - | D8: 22 | E8: =+SUMIF('BAL N'!J:J,"=601",'BAL N'!G:G) -> 0 | F8: =+SUMIF('BAL N-1'!J:J,"=601",'BAL N-1'!G:G) -> 0
A9: RB | B9: Variation de stocks de marchandises | C9: -/+ | D9: 6 | E9: =-(+SUMIF('BAL N'!K:K,"=6031",'BAL N'!H:H)-SUMIF('BAL N'!K:K,"=6031",'BAL N'!G:G)) -> 0 | F9: =-(+SUMIF('BAL N-1'!K:K,"=6031",'BAL N-1'!H:H)-SUMIF('BAL N-1'!K:K,"=6031",'BAL N-1'!G:G)) -> 0
A10: XA | B10: MARGE BRUTE SUR MARCHANDISES (somme TA à RB) | E10: =+E14-E8-E9 -> 5294648115 | F10: =+F14-F8-F9 -> 6032644508
A11: TB | B11: Ventes de produits fabriqués B | C11: + | D11: 21 | E11: =+SUMIF('BAL N'!J:J,"=702",'BAL N'!H:H)+SUMIF('BAL N'!J:J,"=703",'BAL N'!H:H)+SUMIF('BAL N'!J:J,"=704",'BAL N'!H:H) -> 5294648115 | F11: =+SUMIF('BAL N-1'!J:J,"=702",'BAL N-1'!H:H)+SUMIF('BAL N-1'!J:J,"=703",'BAL N-1'!H:H)+SUMIF('BAL N-1'!J:J,"=704",'BAL N-1'!H:H) -> 6032644508
A12: TC | B12: Travaux, services vendus C | C12: + | D12: 21 | E12: =+SUMIF('BAL N'!J:J,"=705",'BAL N'!H:H)+SUMIF('BAL N'!J:J,"=706",'BAL N'!H:H) -> 0 | F12: =+SUMIF('BAL N-1'!J:J,"=705",'BAL N-1'!H:H)+SUMIF('BAL N-1'!J:J,"=706",'BAL N-1'!H:H) -> 0
A13: TD | B13: Produits accessoires D | C13: + | D13: 21 | E13: =+SUMIF('BAL N'!J:J,"=707",'BAL N'!H:H) -> 0 | F13: =+SUMIF('BAL N-1'!J:J,"=707",'BAL N-1'!H:H) -> 0
A14: XB | B14: CHIFFRE D'AFFAIRES (A + B + C + D) | E14: =+E7+E13+E12+E11 -> 5294648115 | F14: =+F7+F13+F12+F11 -> 6032644508
A15: TE | B15: Production stockée (ou destockage) | C15: -/+ | D15: 6 | E15: =+SUMIF('BAL N'!I:I,"=73",'BAL N'!H:H) -> 0 | F15: =+SUMIF('BAL N-1'!I:I,"=73",'BAL N-1'!H:H) -> 0
A16: TF | B16: Production immobilisée | D16: 21 | E16: =+SUMIF('BAL N'!I:I,"=72",'BAL N'!H:H) -> 0 | F16: =+SUMIF('BAL N-1'!I:I,"=72",'BAL N-1'!H:H) -> 0
A17: TG | B17: Subventions d'exploitation | D17: 21 | E17: =+SUMIF('BAL N'!I:I,"=71",'BAL N'!H:H) -> 0 | F17: =+SUMIF('BAL N-1'!I:I,"=71",'BAL N-1'!H:H) -> 0
A18: TH | B18: Autres produits | C18: + | D18: 21 | E18: =+SUMIF('BAL N'!I:I,"=75",'BAL N'!H:H) -> 0 | F18: =+SUMIF('BAL N-1'!I:I,"=75",'BAL N-1'!H:H) -> 0
A19: TI | B19: Transferts de charges d'exploitation | C19: + | D19: 12 | E19: =+SUMIF('BAL N'!J:J,"=781",'BAL N'!H:H) -> 0 | F19: =+SUMIF('BAL N-1'!J:J,"=781",'BAL N-1'!H:H) -> 0
A20: RC | B20: Achats de matières premières et fournitures liées | C20: - | D20: 22 | E20: =+SUMIF('BAL N'!J:J,"=602",'BAL N'!G:G) -> 4195693297 | F20: =+SUMIF('BAL N-1'!J:J,"=602",'BAL N-1'!G:G) -> 4805921959
A21: RD | B21: Variation de stocks de stocks de matières premières et fournitures liées | C21: -/+ | D21: 6 | E21: =-SUMIF('BAL N'!K:K,"=6032",'BAL N'!H:H)+SUMIF('BAL N'!K:K,"=6032",'BAL N'!G:G)-SUMIF('BAL N'!K:K,"=6034",'BAL N'!H:H)+SUMIF('BAL N'!K:K,"=6034",'BAL N'!G:G) -> 68478845 | F21: =-SUMIF('BAL N-1'!K:K,"=6032",'BAL N-1'!H:H)+SUMIF('BAL N-1'!K:K,"=6032",'BAL N-1'!G:G)-SUMIF('BAL N-1'!K:K,"=6034",'BAL N-1'!H:H)+SUMIF('BAL N-1'!K:K,"=6034",'BAL N-1'!G:G) -> -66625516
A22: RE | B22: Autres achats | C22: - | D22: 22 | E22: =+SUMIF('BAL N'!J:J,"=604",'BAL N'!G:G)+SUMIF('BAL N'!J:J,"=605",'BAL N'!G:G)+SUMIF('BAL N'!J:J,"=608",'BAL N'!G:G)+SUMIF('BAL N'!J:J,"=606",'BAL N'!G:G) -> 239426821 | F22: =+SUMIF('BAL N-1'!J:J,"=604",'BAL N-1'!G:G)+SUMIF('BAL N-1'!J:J,"=605",'BAL N-1'!G:G)+SUMIF('BAL N-1'!J:J,"=608",'BAL N-1'!G:G)+SUMIF('BAL N-1'!J:J,"=606",'BAL N-1'!G:G) -> 459241124
A23: RF | B23: Variation de stocks d'autres approvisionnements | C23: -/+ | D23: 6 | E23: =+SUMIF('BAL N'!K:K,"=6033",'BAL N'!H:H)-SUMIF('BAL N'!K:K,"=6033",'BAL N'!G:G) -> 0 | F23: =+SUMIF('BAL N-1'!K:K,"=6033",'BAL N-1'!H:H)-SUMIF('BAL N-1'!K:K,"=6033",'BAL N-1'!G:G) -> 0
A24: RG | B24: Transports | C24: - | D24: 23 | E24: =+SUMIF('BAL N'!I:I,"=61",'BAL N'!G:G) -> 108008609 | F24: =+SUMIF('BAL N-1'!I:I,"=61",'BAL N-1'!G:G) -> 130715952
A25: RH | B25: Services extérieurs | C25: - | D25: 24 | E25: =+SUMIF('BAL N'!I:I,"=62",'BAL N'!G:G)+SUMIF('BAL N'!I:I,"=63",'BAL N'!G:G) -> 281499882 | F25: =+SUMIF('BAL N-1'!I:I,"=62",'BAL N-1'!G:G)+SUMIF('BAL N-1'!I:I,"=63",'BAL N-1'!G:G) -> 383033096
A26: RI | B26: Impôts et taxes | C26: - | D26: 25 | E26: =+SUMIF('BAL N'!I:I,"=64",'BAL N'!G:G) -> 5166230 | F26: =+SUMIF('BAL N-1'!I:I,"=64",'BAL N-1'!G:G) -> 431794
A27: RJ | B27: Autres charges | C27: - | D27: 26 | E27: =+SUMIF('BAL N'!I:I,"=65",'BAL N'!G:G) -> 2100000 | F27: =+SUMIF('BAL N-1'!I:I,"=65",'BAL N-1'!G:G) -> 6638784
A28: XC | B28: VALEUR AJOUTEE (XB + RA + RB) + (somme TE à RJ) | E28: =+E10+E15+E16+E17+E18+E19-E20-E21-E22-E23-E24-E25-E26-E27 -> 394274431 | F28: =+F10+F15+F16+F17+F18+F19-F20-F21-F22-F23-F24-F25-F26-F27 -> 313287315
A29: RK | B29: Charges de personnel | C29: - | D29: 27 | E29: =+SUMIF('BAL N'!I:I,"=66",'BAL N'!G:G) -> 123776550 | F29: =+SUMIF('BAL N-1'!I:I,"=66",'BAL N-1'!G:G) -> 76234787
A30: XD | B30: EXCEDENT BRUT D'EXPLOITATION (XC + RK) | E30: =+E28-E29 -> 270497881 | F30: =+F28-F29 -> 237052528
A31: TJ | B31: Reprises d'amortissements, provisions et dépréciations | C31: + | D31: 28 | E31: =+SUMIF('BAL N'!J:J,"=791",'BAL N'!H:H)+SUMIF('BAL N'!J:J,"=798",'BAL N'!H:H)+SUMIF('BAL N'!J:J,"=799",'BAL N'!H:H) -> 0 | F31: =+SUMIF('BAL N-1'!J:J,"=791",'BAL N-1'!H:H)+SUMIF('BAL N-1'!J:J,"=798",'BAL N-1'!H:H)+SUMIF('BAL N-1'!J:J,"=799",'BAL N-1'!H:H) -> 0
A32: RL | B32: Dotations aux amortissements, aux provisions et dépréciations | C32: - | D32: 3C & 28 | E32: =+SUMIF('BAL N'!J:J,"=681",'BAL N'!G:G)+SUMIF('BAL N'!J:J,"=691",'BAL N'!G:G) -> 167527975 | F32: =+SUMIF('BAL N-1'!J:J,"=681",'BAL N-1'!G:G)+SUMIF('BAL N-1'!J:J,"=691",'BAL N-1'!G:G) -> 122873921
A33: XE | B33: RESULTAT D'EXPLOITATION (XD + TJ + RL) | E33: =+E30+E31-E32 -> 102969906 | F33: =+F30+F31-F32 -> 114178607
A34: TK | B34: Revenus financiers et assimilés | C34: + | D34: 29 | E34: =+SUMIF('BAL N'!I:I,"=77",'BAL N'!H:H) -> 0 | F34: =+SUMIF('BAL N-1'!I:I,"=77",'BAL N-1'!H:H) -> 0
A35: TL | B35: Reprises de provisions et dépréciations financières | C35: + | D35: 28 | E35: =+SUMIF('BAL N'!J:J,"=797",'BAL N'!H:H) -> 0 | F35: =+SUMIF('BAL N-1'!J:J,"=797",'BAL N-1'!H:H) -> 0
A36: TM | B36: Tranferts de charges financières | C36: + | D36: 12 | E36: =+SUMIF('BAL N'!J:J,"=787",'BAL N'!H:H) -> 0 | F36: =+SUMIF('BAL N-1'!J:J,"=787",'BAL N-1'!H:H) -> 0
A37: RM | B37: Frais financiers et charges assimilées | C37: - | D37: 29 | E37: =+SUMIF('BAL N'!I:I,"=67",'BAL N'!G:G) -> 0 | F37: =+SUMIF('BAL N-1'!I:I,"=67",'BAL N-1'!G:G) -> 0
A38: RN | B38: Dotations aux provisions et aux dépréciations financières | C38: - | D38: 3C & 28 | E38: =SUMIF('BAL N'!J:J,"=697",'BAL N'!G:G) -> 0 | F38: =+SUMIF('BAL N-1'!J:J,"=697",'BAL N-1'!G:G) -> 0
A39: XF | B39: RESULTAT FINANCIER (somme TK à RN) | E39: =+E34+E35+E36-E37-E38 -> 0 | F39: =+F34+F35+F36-F37-F38 -> 0
A40: XG | B40: RESULTAT DES ACTIVITES ORDINAIRES (XE + XF) | E40: =+E33+E39 -> 102969906 | F40: =+F33+F39 -> 114178607
A41: TN | B41: Produits des cessions d'immobilisations | C41: + | D41: 3D | E41: =+SUMIF('BAL N'!I:I,"=82",'BAL N'!H:H) -> 0 | F41: =+SUMIF('BAL N-1'!I:I,"=82",'BAL N-1'!H:H) -> 0
A42: TO | B42: Autres produits H.A.O. | C42: + | D42: 30 | E42: =+SUMIF('BAL N'!I:I,"=84",'BAL N'!H:H)+SUMIF('BAL N'!I:I,"=86",'BAL N'!H:H)+SUMIF('BAL N'!I:I,"=88",'BAL N'!H:H) -> 0 | F42: =+SUMIF('BAL N-1'!I:I,"=84",'BAL N-1'!H:H)+SUMIF('BAL N-1'!I:I,"=86",'BAL N-1'!H:H) -> 0
...

Sheet FLUX DE TRESORERIE
A1: FLUX DE TRESORERIE
A3: Désignation entité : | B3: ='Fiche de renseignement R1'!$J$4 -> 0 | D3: Excercice clos le : | E3: =+'Fiche de renseignement R1'!$V$10 -> 0
A4: Numéro d'identification : | B4: =+'Fiche de renseignement R1'!$J$10 -> 0 | D4: Durée en mois : | E4: =+'Fiche de renseignement R1'!$AH$10 -> 12
A6: REF | B6: LIBELLES | D6: NOTE | E6: =IFERROR("31/12/"&YEAR('Fiche de renseignement R1'!V10),"Exercice au 31/12/N") -> 31/12/1900 | F6: =IFERROR("31/12/"&YEAR('Fiche de renseignement R1'!Q20),"Exercice au 31/12/N-1") -> 31/12/2020
A7: ZA | B7: Trésorerie nette au 1er janvier (Trésorerie actif N-1 - Trésorerie passif N-1) | C7: A | E7: ='BILAN PAYSAGE'!F34-'BILAN PAYSAGE'!K34 -> 220952890 | F7: -
B8: Flux de trésorerie provenant des activités opérationnelles
A9: FA | B9: Capacité d'Autofinancement Globale (CAFG) | E9: ='COMPTE DE RESULTAT'!E48+'COMPTE DE RESULTAT'!E32-'COMPTE DE RESULTAT'!E31-'COMPTE DE RESULTAT'!E45 -> 255052531 | F9: -
A10: FB | B10: - Variation d'actif circulant HAO (1)
A11: FC | B11: - Variation des stocks | E11: =+'BILAN PAYSAGE'!F25-'BILAN PAYSAGE'!G25 -> -68478845 | F11: -
A12: FD | B12: - Variation des créances | E12: =+('BILAN PAYSAGE'!F27-'BILAN PAYSAGE'!G27)+('BILAN PAYSAGE'!F28-'BILAN PAYSAGE'!G28)+('BILAN PAYSAGE'!F29-'BILAN PAYSAGE'!G29) -> -1596121233 | F12: -
A13: FE | B13: + Variation du passif circulant (1) | E13: =+'BILAN PAYSAGE'!K30-'BILAN PAYSAGE'!L30 -> 5318273558 | F13: -
B14: Variation du BF lié aux activités opérationnelles (FB + FC + FD + FE) : ……………………………………………..
A15: ZB | B15: Flux de trésorerie provenant des activités opérationnelles (somme FA à FE) | C15: B | E15: =+E9-E10-E11-E12+E13 -> 7237926167 | F15: =IFERROR(+F9-F10-F11-F12+F13,0) -> 0
B16: Flux de trésorerie provenant des activités d'investissement
A17: FF | B17: - Décaissements liés aux acquisitions d'immobilisations incorporelles | E17: =+SUMIF('BAL N'!J:J,"=211",'BAL N'!E:E)+SUMIF('BAL N'!J:J,"=212",'BAL N'!E:E)+SUMIF('BAL N'!J:J,"=213",'BAL N'!E:E)+SUMIF('BAL N'!J:J,"=214",'BAL N'!E:E)+SUMIF('BAL N'!J:J,"=215",'BAL N'!E:E)+SUMIF('BAL N'!J:J,"=216",'BAL N'!E:E)+SUMIF('BAL N'!J:J,"=217",'BAL N'!E:E)+SUMIF('BAL N'!J:J,"=218",'BAL N'!E:E) -> 0 | F17: -
A18: FG | B18: - Décaissements liés aux acquisitions d'immobilisations corporelles | E18: =+SUMIF('BAL N'!I:I,"=22",'BAL N'!E:E)+SUMIF('BAL N'!I:I,"=23",'BAL N'!E:E)+SUMIF('BAL N'!I:I,"=24",'BAL N'!E:E) -> 705861271 | F18: -
A19: FH | B19: - Décaissements liés aux acquisitions d'immobilisations financières | E19: =(+SUMIF('BAL N'!I:I,"=25",'BAL N'!E:E)+SUMIF('BAL N'!I:I,"=26",'BAL N'!E:E)+SUMIF('BAL N'!I:I,"=27",'BAL N'!E:E)) -> 0 | F19: -
A20: FI | B20: + Encaissements liés aux cessions d'immobilisations incorporelles et corporelles | E20: =+SUMIF('BAL N'!I:I,"=82",'BAL N'!H:H) -> 0 | F20: -
A21: FJ | B21: + Encaissements liés aux cessions d'immobilisations financières
A22: ZC | B22: Flux de trésorerie provenant des activités d'investissement (somme FF à FJ) | C22: C | E22: =-E17-E18-E19+E20+E21 -> -705861271 | F22: =IFERROR(-F17-F18-F19+F20+F21,0) -> 0
B23: Flux de trésorerie provenant du financement par les capitaux propres
A24: FK | B24: + Augmentations de capital par apports nouveaux
A25: FL | B25: + Subventions d'investissements reçues | E25: =+SUMIF('BAL N'!I:I,"=14",'BAL N'!F:F) -> 0 | F25: -
A26: FM | B26: - Prélèvements sur le capital
A27: FN | B27: - Dividendes versés
A28: ZD | B28: Flux de trésorerie provenant des capitaux propres (somme FK à FN) | C28: D | E28: =+E24+E25-E26-E27 -> 0 | F28: =IFERROR(+F24+F25-F26-F27,0) -> 0
B29: Flux de trésorerie provenant du financement par les capitaux étrangers
A30: FO | B30: + Emprunts | E30: =+SUMIF('BAL N'!J:J,"=161",'BAL N'!F:F)+SUMIF('BAL N'!J:J,"=162",'BAL N'!F:F)+SUMIF('BAL N'!K:K,"=1661",'BAL N'!F:F)+SUMIF('BAL N'!K:K,"=1662",'BAL N'!F:F) -> 0 | F30: -
A31: FP | B31: + Autres dettes financières | E31: =+SUMIF('BAL N'!I:I,"=17",'BAL N'!H:H) -> 0 | F31: -
A32: FQ | B32: - Remboursements des emprunts et autres dettes financières | E32: =+SUMIF('BAL N'!I:I,"=16",'BAL N'!E:E)+SUMIF('BAL N'!I:I,"=17",'BAL N'!E:E)+SUMIF('BAL N'!I:I,"=18",'BAL N'!E:E) -> 0 | F32: -
A33: ZE | B33: Flux de trésorerie provenant des capitaux étrangers (somme FO à FQ) | C33: E | E33: =+E30+E31-E32 -> 0 | F33: =IFERROR(+F30+F31-F32,0) -> 0
A34: ZF | B34: Flux de trésorerie provenant des activités de financement (D + E) | C34: F | E34: =+E28+E33 -> 0 | F34: =+F28+F33 -> 0
A35: ZG | B35: VARIATION DE LA TRESORERIE NETTE DE LA PERIODE (B + C + F) | C35: G | E35: =+E34+E22+E15 -> 6532064896 | F35: =IFERROR(+F34+F22+F15,0) -> 0
A36: ZH | B36: Trésorerie nette au 31 décembre (G + A) Contrôle : Trésorerie actif N - Trésorerie passif N | C36: H | E36: =+E35+E7 -> 6753017786 | F36: =IFERROR(+F35+F7,0) -> 0
B37: Contrôle

Sheet Note 1
A1: NOTE 1 : DETTES GARANTIES PAR DES SURETES REELLES
A3: Désignation entité : | B3: ='Fiche de renseignement R1'!$J$4 -> 0 | D3: Excercice clos le : | E3: =+'Fiche de renseignement R1'!$V$10 -> 0
A4: Numéro d'identification : | B4: =+'Fiche de renseignement R1'!$J$10 -> 0 | D4: Durée en mois : | E4: =+'Fiche de renseignement R1'!$AH$10 -> 12
A7: LIBELLES | B7: Note | C7: Montant brut | D7: SURETES REELLES
D8: Hypothèques | E8: Nantissements | F8: Gages
F9: Autres
A10: Dettes financières et ressources assimilées :
A11: Emprunts obligataires convertibles | C11: =+SUMIF('BAL N'!K:K,"=1612",'BAL N'!H:H) -> 0
